Workbook
Name ArmenianHolidays: Holidays!$A$2:$A$92
Name LoanAmount: Inputs!$B$4
Name AnnualRate: Inputs!$B$5
Name FeeRate: Inputs!$B$6
Name StartDate: Inputs!$B$8
Name FirstPayDate: Inputs!$B$9
Name Tenure: Inputs!$B$10
Name DayConvention: Inputs!$B$12
Name ExtraPayMode: Inputs!$B$13
Name MonthlyRate: Inputs!$B$16
Name EMI: Inputs!$B$17

Sheet Holidays
A1: Armenian Public Holidays
A2: 45292
A3: 45293
A4: 45297
A5: 45318
A6: 45319
A7: 45359
A8: 45406
A9: 45413
A10: 45421
A11: 45440
A12: 45478
A13: 45556
... A92: 47848

Sheet Inputs
A1: DC LOAN CALCULATOR — Amortized Schedule
A2: Parameter | B2: Value | C2: Units / Notes
A3: LOAN PARAMETERS
A4: Loan Amount | B4: 1500000 | C4: AMD
A5: Annual Interest Rate | B5: 0.11 | C5: Daily % stored in DB (0.11 = 0.11%/day = 40.15%/yr) — e.g. contract 28 = 0.11
A6: Annual Fee Rate | B6: 0 | C6: Decimal (0.02 = 2%)
A8: Loan Start Date | B8: 46091 | C8: YYYY-MM-DD
A9: First Payment Date | B9: 46122 | C9: YYYY-MM-DD
A10: Tenure (months) | B10: 60 | C10: months
A11: CONFIGURATION
A12: Day Count Convention | B12: Actual | C12: dropdown
A13: Extra Payment Mode | B13: Reduce Tenure | C13: dropdown
A15: DERIVED CALCULATIONS (formulas — do not edit)
A16: Combined Monthly Rate | B16: =B5*365/100/12+B6/100/12 | C16: Source: ContractService.php L466-467 — interestAnnualPercent = rate*365 → monthlyRate = annualPercent/100/12 (rate stored as daily-%, so *365 gives annual-%, /100 gives decimal, /12 gives monthly)
A17: Monthly Payment (EMI) | B17: =-PMT(B16,B10,B4) | C17: Source: ContractService.php L474 — -excelPmt(allMonthlyRate, months, loanAmount)
A18: Total Scheduled Payments | B18: =B17*B10 | C18: Sum of all EMIs
A19: Total Interest + Fee Cost | B19: =B18-B4 | C19: Total cost of credit
A20: Effective Annual Rate (approx) | B20: =(1+B16)^12-1 | C20: Approximate — backend uses XIRR; see EffectiveRateService.php

Sheet Schedule
A1: AMORTIZATION SCHEDULE — DC_New_backend logic
A2: # | B2: Period Start | C2: Due Date (adj.) | D2: Days | E2: Opening Balance | F2: Accrued Interest | G2: Principal Due | H2: Payment Received | I2: Payment Date | J2: Interest Paid | K2: Principal Paid | L2: Unpaid Carried | M2: Closing Balance | N2: Status
A3: =IF(1<=Tenure,1,"") | B3: =IF(1<=Tenure,StartDate,"") | C3: =IF(1<=Tenure,WORKDAY.INTL(EDATE(FirstPayDate,0)-1,1,1,ArmenianHolidays),"") | D3: =IF(1<=Tenure,IF(1=Tenure,C3-StartDate+1,C3-StartDate),"") | E3: =IF(1<=Tenure,LoanAmount,"") | F3: =IF(1<=Tenure,E3*D3*(AnnualRate/100),"") | G3: =IF(1<=Tenure,IF(1=Tenure,E3,EMI-F3),"") | H3: =IF(1<=Tenure,IFERROR(SUMIFS(Payments!$C:$C,Payments!$B:$B,A3),0),"") | I3: =IF(1<=Tenure,IFERROR(AGGREGATE(15,6,Payments!$A$3:$A$200/(Payments!$B$3:$B$200=A3),1),""),"") | J3: =IF(1<=Tenure,IF(H3=0,0,IF(AND(I3<>"",I3<>0,I3<C3),MIN(F3,MAX(0,H3-K3)-IFERROR(MIN(MAX(0,(MAX(0,H3-K3)-F3)/(1-MAX(0,C3-I3)*(AnnualRate/100))),E3,MAX(0,H3-K3)),0)),MIN(F3,MAX(0,H3-K3)))),"") | K3: =IF(1<=Tenure,IF(H3=0,0,MIN(E3,MAX(0,MAX(0,H3-K3)-L3))),"") | L3: =IF(1<=Tenure,MAX(0,F3+G3+J3-K3-L3-M3),"") | M3: =IF(1<=Tenure,IF(1=Tenure,0,MAX(0,E3-M3)),"") | N3: =IF(1>Tenure,"",IF(AND(H3>0,H3>=F3+G3+J3),"Paid",IF(AND(H3>0,H3<F3+G3),"Partial",IF(AND(H3=0,TODAY()>C3),"Overdue","Pending"))))
A4: =IF(2<=Tenure,2,"") | B4: =IF(2<=Tenure,C3,"") | C4: =IF(2<=Tenure,WORKDAY.INTL(EDATE(FirstPayDate,1)-1,1,1,ArmenianHolidays),"") | D4: =IF(2<=Tenure,IF(2=Tenure,C4-C3+1,C4-C3),"") | E4: =IF(2<=Tenure,O3,"") | F4: =IF(2<=Tenure,E4*D4*(AnnualRate/100),"") | G4: =IF(2<=Tenure,IF(2=Tenure,E4,EMI-F4),"") | H4: =IF(2<=Tenure,IFERROR(SUMIFS(Payments!$C:$C,Payments!$B:$B,A4),0),"") | I4: =IF(2<=Tenure,IFERROR(AGGREGATE(15,6,Payments!$A$3:$A$200/(Payments!$B$3:$B$200=A4),1),""),"") | J4: =IF(2<=Tenure,IF(H4=0,0,IF(AND(I4<>"",I4<>0,I4<C4),MIN(F4,MAX(0,H4-K4)-IFERROR(MIN(MAX(0,(MAX(0,H4-K4)-F4)/(1-MAX(0,C4-I4)*(AnnualRate/100))),E4,MAX(0,H4-K4)),0)),MIN(F4,MAX(0,H4-K4)))),"") | K4: =IF(2<=Tenure,IF(H4=0,0,MIN(E4,MAX(0,MAX(0,H4-K4)-L4))),"") | L4: =IF(2<=Tenure,MAX(0,F4+G4+J4-K4-L4-M4),"") | M4: =IF(2<=Tenure,IF(2=Tenure,0,MAX(0,E4-M4)),"") | N4: =IF(2>Tenure,"",IF(AND(H4>0,H4>=F4+G4+J4),"Paid",IF(AND(H4>0,H4<F4+G4),"Partial",IF(AND(H4=0,TODAY()>C4),"Overdue","Pending"))))
A5: =IF(3<=Tenure,3,"") | B5: =IF(3<=Tenure,C4,"") | C5: =IF(3<=Tenure,WORKDAY.INTL(EDATE(FirstPayDate,2)-1,1,1,ArmenianHolidays),"") | D5: =IF(3<=Tenure,IF(3=Tenure,C5-C4+1,C5-C4),"") | E5: =IF(3<=Tenure,O4,"") | F5: =IF(3<=Tenure,E5*D5*(AnnualRate/100),"") | G5: =IF(3<=Tenure,IF(3=Tenure,E5,EMI-F5),"") | H5: =IF(3<=Tenure,IFERROR(SUMIFS(Payments!$C:$C,Payments!$B:$B,A5),0),"") | I5: =IF(3<=Tenure,IFERROR(AGGREGATE(15,6,Payments!$A$3:$A$200/(Payments!$B$3:$B$200=A5),1),""),"") | J5: =IF(3<=Tenure,IF(H5=0,0,IF(AND(I5<>"",I5<>0,I5<C5),MIN(F5,MAX(0,H5-K5)-IFERROR(MIN(MAX(0,(MAX(0,H5-K5)-F5)/(1-MAX(0,C5-I5)*(AnnualRate/100))),E5,MAX(0,H5-K5)),0)),MIN(F5,MAX(0,H5-K5)))),"") | K5: =IF(3<=Tenure,IF(H5=0,0,MIN(E5,MAX(0,MAX(0,H5-K5)-L5))),"") | L5: =IF(3<=Tenure,MAX(0,F5+G5+J5-K5-L5-M5),"") | M5: =IF(3<=Tenure,IF(3=Tenure,0,MAX(0,E5-M5)),"") | N5: =IF(3>Tenure,"",IF(AND(H5>0,H5>=F5+G5+J5),"Paid",IF(AND(H5>0,H5<F5+G5),"Partial",IF(AND(H5=0,TODAY()>C5),"Overdue","Pending"))))
A6: =IF(4<=Tenure,4,"") | B6: =IF(4<=Tenure,C5,"") | C6: =IF(4<=Tenure,WORKDAY.INTL(EDATE(FirstPayDate,3)-1,1,1,ArmenianHolidays),"") | D6: =IF(4<=Tenure,IF(4=Tenure,C6-C5+1,C6-C5),"") | E6: =IF(4<=Tenure,O5,"") | F6: =IF(4<=Tenure,E6*D6*(AnnualRate/100),"") | G6: =IF(4<=Tenure,IF(4=Tenure,E6,EMI-F6),"") | H6: =IF(4<=Tenure,IFERROR(SUMIFS(Payments!$C:$C,Payments!$B:$B,A6),0),"") | I6: =IF(4<=Tenure,IFERROR(AGGREGATE(15,6,Payments!$A$3:$A$200/(Payments!$B$3:$B$200=A6),1),""),"") | J6: =IF(4<=Tenure,IF(H6=0,0,IF(AND(I6<>"",I6<>0,I6<C6),MIN(F6,MAX(0,H6-K6)-IFERROR(MIN(MAX(0,(MAX(0,H6-K6)-F6)/(1-MAX(0,C6-I6)*(AnnualRate/100))),E6,MAX(0,H6-K6)),0)),MIN(F6,MAX(0,H6-K6)))),"") | K6: =IF(4<=Tenure,IF(H6=0,0,MIN(E6,MAX(0,MAX(0,H6-K6)-L6))),"") | L6: =IF(4<=Tenure,MAX(0,F6+G6+J6-K6-L6-M6),"") | M6: =IF(4<=Tenure,IF(4=Tenure,0,MAX(0,E6-M6)),"") | N6: =IF(4>Tenure,"",IF(AND(H6>0,H6>=F6+G6+J6),"Paid",IF(AND(H6>0,H6<F6+G6),"Partial",IF(AND(H6=0,TODAY()>C6),"Overdue","Pending"))))
A7: =IF(5<=Tenure,5,"") | B7: =IF(5<=Tenure,C6,"") | C7: =IF(5<=Tenure,WORKDAY.INTL(EDATE(FirstPayDate,4)-1,1,1,ArmenianHolidays),"") | D7: =IF(5<=Tenure,IF(5=Tenure,C7-C6+1,C7-C6),"") | E7: =IF(5<=Tenure,O6,"") | F7: =IF(5<=Tenure,E7*D7*(AnnualRate/100),"") | G7: =IF(5<=Tenure,IF(5=Tenure,E7,EMI-F7),"") | H7: =IF(5<=Tenure,IFERROR(SUMIFS(Payments!$C:$C,Payments!$B:$B,A7),0),"") | I7: =IF(5<=Tenure,IFERROR(AGGREGATE(15,6,Payments!$A$3:$A$200/(Payments!$B$3:$B$200=A7),1),""),"") | J7: =IF(5<=Tenure,IF(H7=0,0,IF(AND(I7<>"",I7<>0,I7<C7),MIN(F7,MAX(0,H7-K7)-IFERROR(MIN(MAX(0,(MAX(0,H7-K7)-F7)/(1-MAX(0,C7-I7)*(AnnualRate/100))),E7,MAX(0,H7-K7)),0)),MIN(F7,MAX(0,H7-K7)))),"") | K7: =IF(5<=Tenure,IF(H7=0,0,MIN(E7,MAX(0,MAX(0,H7-K7)-L7))),"") | L7: =IF(5<=Tenure,MAX(0,F7+G7+J7-K7-L7-M7),"") | M7: =IF(5<=Tenure,IF(5=Tenure,0,MAX(0,E7-M7)),"") | N7: =IF(5>Tenure,"",IF(AND(H7>0,H7>=F7+G7+J7),"Paid",IF(AND(H7>0,H7<F7+G7),"Partial",IF(AND(H7=0,TODAY()>C7),"Overdue","Pending"))))
A8: =IF(6<=Tenure,6,"") | B8: =IF(6<=Tenure,C7,"") | C8: =IF(6<=Tenure,WORKDAY.INTL(EDATE(FirstPayDate,5)-1,1,1,ArmenianHolidays),"") | D8: =IF(6<=Tenure,IF(6=Tenure,C8-C7+1,C8-C7),"") | E8: =IF(6<=Tenure,O7,"") | F8: =IF(6<=Tenure,E8*D8*(AnnualRate/100),"") | G8: =IF(6<=Tenure,IF(6=Tenure,E8,EMI-F8),"") | H8: =IF(6<=Tenure,IFERROR(SUMIFS(Payments!$C:$C,Payments!$B:$B,A8),0),"") | I8: =IF(6<=Tenure,IFERROR(AGGREGATE(15,6,Payments!$A$3:$A$200/(Payments!$B$3:$B$200=A8),1),""),"") | J8: =IF(6<=Tenure,IF(H8=0,0,IF(AND(I8<>"",I8<>0,I8<C8),MIN(F8,MAX(0,H8-K8)-IFERROR(MIN(MAX(0,(MAX(0,H8-K8)-F8)/(1-MAX(0,C8-I8)*(AnnualRate/100))),E8,MAX(0,H8-K8)),0)),MIN(F8,MAX(0,H8-K8)))),"") | K8: =IF(6<=Tenure,IF(H8=0,0,MIN(E8,MAX(0,MAX(0,H8-K8)-L8))),"") | L8: =IF(6<=Tenure,MAX(0,F8+G8+J8-K8-L8-M8),"") | M8: =IF(6<=Tenure,IF(6=Tenure,0,MAX(0,E8-M8)),"") | N8: =IF(6>Tenure,"",IF(AND(H8>0,H8>=F8+G8+J8),"Paid",IF(AND(H8>0,H8<F8+G8),"Partial",IF(AND(H8=0,TODAY()>C8),"Overdue","Pending"))))
A9: =IF(7<=Tenure,7,"") | B9: =IF(7<=Tenure,C8,"") | C9: =IF(7<=Tenure,WORKDAY.INTL(EDATE(FirstPayDate,6)-1,1,1,ArmenianHolidays),"") | D9: =IF(7<=Tenure,IF(7=Tenure,C9-C8+1,C9-C8),"") | E9: =IF(7<=Tenure,O8,"") | F9: =IF(7<=Tenure,E9*D9*(AnnualRate/100),"") | G9: =IF(7<=Tenure,IF(7=Tenure,E9,EMI-F9),"") | H9: =IF(7<=Tenure,IFERROR(SUMIFS(Payments!$C:$C,Payments!$B:$B,A9),0),"") | I9: =IF(7<=Tenure,IFERROR(AGGREGATE(15,6,Payments!$A$3:$A$200/(Payments!$B$3:$B$200=A9),1),""),"") | J9: =IF(7<=Tenure,IF(H9=0,0,IF(AND(I9<>"",I9<>0,I9<C9),MIN(F9,MAX(0,H9-K9)-IFERROR(MIN(MAX(0,(MAX(0,H9-K9)-F9)/(1-MAX(0,C9-I9)*(AnnualRate/100))),E9,MAX(0,H9-K9)),0)),MIN(F9,MAX(0,H9-K9)))),"") | K9: =IF(7<=Tenure,IF(H9=0,0,MIN(E9,MAX(0,MAX(0,H9-K9)-L9))),"") | L9: =IF(7<=Tenure,MAX(0,F9+G9+J9-K9-L9-M9),"") | M9: =IF(7<=Tenure,IF(7=Tenure,0,MAX(0,E9-M9)),"") | N9: =IF(7>Tenure,"",IF(AND(H9>0,H9>=F9+G9+J9),"Paid",IF(AND(H9>0,H9<F9+G9),"Partial",IF(AND(H9=0,TODAY()>C9),"Overdue","Pending"))))
A10: =IF(8<=Tenure,8,"") | B10: =IF(8<=Tenure,C9,"") | C10: =IF(8<=Tenure,WORKDAY.INTL(EDATE(FirstPayDate,7)-1,1,1,ArmenianHolidays),"") | D10: =IF(8<=Tenure,IF(8=Tenure,C10-C9+1,C10-C9),"") | E10: =IF(8<=Tenure,O9,"") | F10: =IF(8<=Tenure,E10*D10*(AnnualRate/100),"") | G10: =IF(8<=Tenure,IF(8=Tenure,E10,EMI-F10),"") | H10: =IF(8<=Tenure,IFERROR(SUMIFS(Payments!$C:$C,Payments!$B:$B,A10),0),"") | I10: =IF(8<=Tenure,IFERROR(AGGREGATE(15,6,Payments!$A$3:$A$200/(Payments!$B$3:$B$200=A10),1),""),"") | J10: =IF(8<=Tenure,IF(H10=0,0,IF(AND(I10<>"",I10<>0,I10<C10),MIN(F10,MAX(0,H10-K10)-IFERROR(MIN(MAX(0,(MAX(0,H10-K10)-F10)/(1-MAX(0,C10-I10)*(AnnualRate/100))),E10,MAX(0,H10-K10)),0)),MIN(F10,MAX(0,H10-K10)))),"") | K10: =IF(8<=Tenure,IF(H10=0,0,MIN(E10,MAX(0,MAX(0,H10-K10)-L10))),"") | L10: =IF(8<=Tenure,MAX(0,F10+G10+J10-K10-L10-M10),"") | M10: =IF(8<=Tenure,IF(8=Tenure,0,MAX(0,E10-M10)),"") | N10: =IF(8>Tenure,"",IF(AND(H10>0,H10>=F10+G10+J10),"Paid",IF(AND(H10>0,H10<F10+G10),"Partial",IF(AND(H10=0,TODAY()>C10),"Overdue","Pending"))))
A11: =IF(9<=Tenure,9,"") | B11: =IF(9<=Tenure,C10,"") | C11: =IF(9<=Tenure,WORKDAY.INTL(EDATE(FirstPayDate,8)-1,1,1,ArmenianHolidays),"") | D11: =IF(9<=Tenure,IF(9=Tenure,C11-C10+1,C11-C10),"") | E11: =IF(9<=Tenure,O10,"") | F11: =IF(9<=Tenure,E11*D11*(AnnualRate/100),"") | G11: =IF(9<=Tenure,IF(9=Tenure,E11,EMI-F11),"") | H11: =IF(9<=Tenure,IFERROR(SUMIFS(Payments!$C:$C,Payments!$B:$B,A11),0),"") | I11: =IF(9<=Tenure,IFERROR(AGGREGATE(15,6,Payments!$A$3:$A$200/(Payments!$B$3:$B$200=A11),1),""),"") | J11: =IF(9<=Tenure,IF(H11=0,0,IF(AND(I11<>"",I11<>0,I11<C11),MIN(F11,MAX(0,H11-K11)-IFERROR(MIN(MAX(0,(MAX(0,H11-K11)-F11)/(1-MAX(0,C11-I11)*(AnnualRate/100))),E11,MAX(0,H11-K11)),0)),MIN(F11,MAX(0,H11-K11)))),"") | K11: =IF(9<=Tenure,IF(H11=0,0,MIN(E11,MAX(0,MAX(0,H11-K11)-L11))),"") | L11: =IF(9<=Tenure,MAX(0,F11+G11+J11-K11-L11-M11),"") | M11: =IF(9<=Tenure,IF(9=Tenure,0,MAX(0,E11-M11)),"") | N11: =IF(9>Tenure,"",IF(AND(H11>0,H11>=F11+G11+J11),"Paid",IF(AND(H11>0,H11<F11+G11),"Partial",IF(AND(H11=0,TODAY()>C11),"Overdue","Pending"))))
A12: =IF(10<=Tenure,10,"") | B12: =IF(10<=Tenure,C11,"") | C12: =IF(10<=Tenure,WORKDAY.INTL(EDATE(FirstPayDate,9)-1,1,1,ArmenianHolidays),"") | D12: =IF(10<=Tenure,IF(10=Tenure,C12-C11+1,C12-C11),"") | E12: =IF(10<=Tenure,O11,"") | F12: =IF(10<=Tenure,E12*D12*(AnnualRate/100),"") | G12: =IF(10<=Tenure,IF(10=Tenure,E12,EMI-F12),"") | H12: =IF(10<=Tenure,IFERROR(SUMIFS(Payments!$C:$C,Payments!$B:$B,A12),0),"") | I12: =IF(10<=Tenure,IFERROR(AGGREGATE(15,6,Payments!$A$3:$A$200/(Payments!$B$3:$B$200=A12),1),""),"") | J12: =IF(10<=Tenure,IF(H12=0,0,IF(AND(I12<>"",I12<>0,I12<C12),MIN(F12,MAX(0,H12-K12)-IFERROR(MIN(MAX(0,(MAX(0,H12-K12)-F12)/(1-MAX(0,C12-I12)*(AnnualRate/100))),E12,MAX(0,H12-K12)),0)),MIN(F12,MAX(0,H12-K12)))),"") | K12: =IF(10<=Tenure,IF(H12=0,0,MIN(E12,MAX(0,MAX(0,H12-K12)-L12))),"") | L12: =IF(10<=Tenure,MAX(0,F12+G12+J12-K12-L12-M12),"") | M12: =IF(10<=Tenure,IF(10=Tenure,0,MAX(0,E12-M12)),"") | N12: =IF(10>Tenure,"",IF(AND(H12>0,H12>=F12+G12+J12),"Paid",IF(AND(H12>0,H12<F12+G12),"Partial",IF(AND(H12=0,TODAY()>C12),"Overdue","Pending"))))
A13: =IF(11<=Tenure,11,"") | B13: =IF(11<=Tenure,C12,"") | C13: =IF(11<=Tenure,WORKDAY.INTL(EDATE(FirstPayDate,10)-1,1,1,ArmenianHolidays),"") | D13: =IF(11<=Tenure,IF(11=Tenure,C13-C12+1,C13-C12),"") | E13: =IF(11<=Tenure,O12,"") | F13: =IF(11<=Tenure,E13*D13*(AnnualRate/100),"") | G13: =IF(11<=Tenure,IF(11=Tenure,E13,EMI-F13),"") | H13: =IF(11<=Tenure,IFERROR(SUMIFS(Payments!$C:$C,Payments!$B:$B,A13),0),"") | I13: =IF(11<=Tenure,IFERROR(AGGREGATE(15,6,Payments!$A$3:$A$200/(Payments!$B$3:$B$200=A13),1),""),"") | J13: =IF(11<=Tenure,IF(H13=0,0,IF(AND(I13<>"",I13<>0,I13<C13),MIN(F13,MAX(0,H13-K13)-IFERROR(MIN(MAX(0,(MAX(0,H13-K13)-F13)/(1-MAX(0,C13-I13)*(AnnualRate/100))),E13,MAX(0,H13-K13)),0)),MIN(F13,MAX(0,H13-K13)))),"") | K13: =IF(11<=Tenure,IF(H13=0,0,MIN(E13,MAX(0,MAX(0,H13-K13)-L13))),"") | L13: =IF(11<=Tenure,MAX(0,F13+G13+J13-K13-L13-M13),"") | M13: =IF(11<=Tenure,IF(11=Tenure,0,MAX(0,E13-M13)),"") | N13: =IF(11>Tenure,"",IF(AND(H13>0,H13>=F13+G13+J13),"Paid",IF(AND(H13>0,H13<F13+G13),"Partial",IF(AND(H13=0,TODAY()>C13),"Overdue","Pending"))))
A14: =IF(12<=Tenure,12,"") | B14: =IF(12<=Tenure,C13,"") | C14: =IF(12<=Tenure,WORKDAY.INTL(EDATE(FirstPayDate,11)-1,1,1,ArmenianHolidays),"") | D14: =IF(12<=Tenure,IF(12=Tenure,C14-C13+1,C14-C13),"") | E14: =IF(12<=Tenure,O13,"") | F14: =IF(12<=Tenure,E14*D14*(AnnualRate/100),"") | G14: =IF(12<=Tenure,IF(12=Tenure,E14,EMI-F14),"") | H14: =IF(12<=Tenure,IFERROR(SUMIFS(Payments!$C:$C,Payments!$B:$B,A14),0),"") | I14: =IF(12<=Tenure,IFERROR(AGGREGATE(15,6,Payments!$A$3:$A$200/(Payments!$B$3:$B$200=A14),1),""),"") | J14: =IF(12<=Tenure,IF(H14=0,0,IF(AND(I14<>"",I14<>0,I14<C14),MIN(F14,MAX(0,H14-K14)-IFERROR(MIN(MAX(0,(MAX(0,H14-K14)-F14)/(1-MAX(0,C14-I14)*(AnnualRate/100))),E14,MAX(0,H14-K14)),0)),MIN(F14,MAX(0,H14-K14)))),"") | K14: =IF(12<=Tenure,IF(H14=0,0,MIN(E14,MAX(0,MAX(0,H14-K14)-L14))),"") | L14: =IF(12<=Tenure,MAX(0,F14+G14+J14-K14-L14-M14),"") | M14: =IF(12<=Tenure,IF(12=Tenure,0,MAX(0,E14-M14)),"") | N14: =IF(12>Tenure,"",IF(AND(H14>0,H14>=F14+G14+J14),"Paid",IF(AND(H14>0,H14<F14+G14),"Partial",IF(AND(H14=0,TODAY()>C14),"Overdue","Pending"))))
A15: =IF(13<=Tenure,13,"") | B15: =IF(13<=Tenure,C14,"") | C15: =IF(13<=Tenure,WORKDAY.INTL(EDATE(FirstPayDate,12)-1,1,1,ArmenianHolidays),"") | D15: =IF(13<=Tenure,IF(13=Tenure,C15-C14+1,C15-C14),"") | E15: =IF(13<=Tenure,O14,"") | F15: =IF(13<=Tenure,E15*D15*(AnnualRate/100),"") | G15: =IF(13<=Tenure,IF(13=Tenure,E15,EMI-F15),"") | H15: =IF(13<=Tenure,IFERROR(SUMIFS(Payments!$C:$C,Payments!$B:$B,A15),0),"") | I15: =IF(13<=Tenure,IFERROR(AGGREGATE(15,6,Payments!$A$3:$A$200/(Payments!$B$3:$B$200=A15),1),""),"") | J15: =IF(13<=Tenure,IF(H15=0,0,IF(AND(I15<>"",I15<>0,I15<C15),MIN(F15,MAX(0,H15-K15)-IFERROR(MIN(MAX(0,(MAX(0,H15-K15)-F15)/(1-MAX(0,C15-I15)*(AnnualRate/100))),E15,MAX(0,H15-K15)),0)),MIN(F15,MAX(0,H15-K15)))),"") | K15: =IF(13<=Tenure,IF(H15=0,0,MIN(E15,MAX(0,MAX(0,H15-K15)-L15))),"") | L15: =IF(13<=Tenure,MAX(0,F15+G15+J15-K15-L15-M15),"") | M15: =IF(13<=Tenure,IF(13=Tenure,0,MAX(0,E15-M15)),"") | N15: =IF(13>Tenure,"",IF(AND(H15>0,H15>=F15+G15+J15),"Paid",IF(AND(H15>0,H15<F15+G15),"Partial",IF(AND(H15=0,TODAY()>C15),"Overdue","Pending"))))
A16: =IF(14<=Tenure,14,"") | B16: =IF(14<=Tenure,C15,"") | C16: =IF(14<=Tenure,WORKDAY.INTL(EDATE(FirstPayDate,13)-1,1,1,ArmenianHolidays),"") | D16: =IF(14<=Tenure,IF(14=Tenure,C16-C15+1,C16-C15),"") | E16: =IF(14<=Tenure,O15,"") | F16: =IF(14<=Tenure,E16*D16*(AnnualRate/100),"") | G16: =IF(14<=Tenure,IF(14=Tenure,E16,EMI-F16),"") | H16: =IF(14<=Tenure,IFERROR(SUMIFS(Payments!$C:$C,Payments!$B:$B,A16),0),"") | I16: =IF(14<=Tenure,IFERROR(AGGREGATE(15,6,Payments!$A$3:$A$200/(Payments!$B$3:$B$200=A16),1),""),"") | J16: =IF(14<=Tenure,IF(H16=0,0,IF(AND(I16<>"",I16<>0,I16<C16),MIN(F16,MAX(0,H16-K16)-IFERROR(MIN(MAX(0,(MAX(0,H16-K16)-F16)/(1-MAX(0,C16-I16)*(AnnualRate/100))),E16,MAX(0,H16-K16)),0)),MIN(F16,MAX(0,H16-K16)))),"") | K16: =IF(14<=Tenure,IF(H16=0,0,MIN(E16,MAX(0,MAX(0,H16-K16)-L16))),"") | L16: =IF(14<=Tenure,MAX(0,F16+G16+J16-K16-L16-M16),"") | M16: =IF(14<=Tenure,IF(14=Tenure,0,MAX(0,E16-M16)),"") | N16: =IF(14>Tenure,"",IF(AND(H16>0,H16>=F16+G16+J16),"Paid",IF(AND(H16>0,H16<F16+G16),"Partial",IF(AND(H16=0,TODAY()>C16),"Overdue","Pending"))))
A17: =IF(15<=Tenure,15,"") | B17: =IF(15<=Tenure,C16,"") | C17: =IF(15<=Tenure,WORKDAY.INTL(EDATE(FirstPayDate,14)-1,1,1,ArmenianHolidays),"") | D17: =IF(15<=Tenure,IF(15=Tenure,C17-C16+1,C17-C16),"") | E17: =IF(15<=Tenure,O16,"") | F17: =IF(15<=Tenure,E17*D17*(AnnualRate/100),"") | G17: =IF(15<=Tenure,IF(15=Tenure,E17,EMI-F17),"") | H17: =IF(15<=Tenure,IFERROR(SUMIFS(Payments!$C:$C,Payments!$B:$B,A17),0),"") | I17: =IF(15<=Tenure,IFERROR(AGGREGATE(15,6,Payments!$A$3:$A$200/(Payments!$B$3:$B$200=A17),1),""),"") | J17: =IF(15<=Tenure,IF(H17=0,0,IF(AND(I17<>"",I17<>0,I17<C17),MIN(F17,MAX(0,H17-K17)-IFERROR(MIN(MAX(0,(MAX(0,H17-K17)-F17)/(1-MAX(0,C17-I17)*(AnnualRate/100))),E17,MAX(0,H17-K17)),0)),MIN(F17,MAX(0,H17-K17)))),"") | K17: =IF(15<=Tenure,IF(H17=0,0,MIN(E17,MAX(0,MAX(0,H17-K17)-L17))),"") | L17: =IF(15<=Tenure,MAX(0,F17+G17+J17-K17-L17-M17),"") | M17: =IF(15<=Tenure,IF(15=Tenure,0,MAX(0,E17-M17)),"") | N17: =IF(15>Tenure,"",IF(AND(H17>0,H17>=F17+G17+J17),"Paid",IF(AND(H17>0,H17<F17+G17),"Partial",IF(AND(H17=0,TODAY()>C17),"Overdue","Pending"))))
A18: =IF(16<=Tenure,16,"") | B18: =IF(16<=Tenure,C17,"") | C18: =IF(16<=Tenure,WORKDAY.INTL(EDATE(FirstPayDate,15)-1,1,1,ArmenianHolidays),"") | D18: =IF(16<=Tenure,IF(16=Tenure,C18-C17+1,C18-C17),"") | E18: =IF(16<=Tenure,O17,"") | F18: =IF(16<=Tenure,E18*D18*(AnnualRate/100),"") | G18: =IF(16<=Tenure,IF(16=Tenure,E18,EMI-F18),"") | H18: =IF(16<=Tenure,IFERROR(SUMIFS(Payments!$C:$C,Payments!$B:$B,A18),0),"") | I18: =IF(16<=Tenure,IFERROR(AGGREGATE(15,6,Payments!$A$3:$A$200/(Payments!$B$3:$B$200=A18),1),""),"") | J18: =IF(16<=Tenure,IF(H18=0,0,IF(AND(I18<>"",I18<>0,I18<C18),MIN(F18,MAX(0,H18-K18)-IFERROR(MIN(MAX(0,(MAX(0,H18-K18)-F18)/(1-MAX(0,C18-I18)*(AnnualRate/100))),E18,MAX(0,H18-K18)),0)),MIN(F18,MAX(0,H18-K18)))),"") | K18: =IF(16<=Tenure,IF(H18=0,0,MIN(E18,MAX(0,MAX(0,H18-K18)-L18))),"") | L18: =IF(16<=Tenure,MAX(0,F18+G18+J18-K18-L18-M18),"") | M18: =IF(16<=Tenure,IF(16=Tenure,0,MAX(0,E18-M18)),"") | N18: =IF(16>Tenure,"",IF(AND(H18>0,H18>=F18+G18+J18),"Paid",IF(AND(H18>0,H18<F18+G18),"Partial",IF(AND(H18=0,TODAY()>C18),"Overdue","Pending"))))
A19: =IF(17<=Tenure,17,"") | B19: =IF(17<=Tenure,C18,"") | C19: =IF(17<=Tenure,WORKDAY.INTL(EDATE(FirstPayDate,16)-1,1,1,ArmenianHolidays),"") | D19: =IF(17<=Tenure,IF(17=Tenure,C19-C18+1,C19-C18),"") | E19: =IF(17<=Tenure,O18,"") | F19: =IF(17<=Tenure,E19*D19*(AnnualRate/100),"") | G19: =IF(17<=Tenure,IF(17=Tenure,E19,EMI-F19),"") | H19: =IF(17<=Tenure,IFERROR(SUMIFS(Payments!$C:$C,Payments!$B:$B,A19),0),"") | I19: =IF(17<=Tenure,IFERROR(AGGREGATE(15,6,Payments!$A$3:$A$200/(Payments!$B$3:$B$200=A19),1),""),"") | J19: =IF(17<=Tenure,IF(H19=0,0,IF(AND(I19<>"",I19<>0,I19<C19),MIN(F19,MAX(0,H19-K19)-IFERROR(MIN(MAX(0,(MAX(0,H19-K19)-F19)/(1-MAX(0,C19-I19)*(AnnualRate/100))),E19,MAX(0,H19-K19)),0)),MIN(F19,MAX(0,H19-K19)))),"") | K19: =IF(17<=Tenure,IF(H19=0,0,MIN(E19,MAX(0,MAX(0,H19-K19)-L19))),"") | L19: =IF(17<=Tenure,MAX(0,F19+G19+J19-K19-L19-M19),"") | M19: =IF(17<=Tenure,IF(17=Tenure,0,MAX(0,E19-M19)),"") | N19: =IF(17>Tenure,"",IF(AND(H19>0,H19>=F19+G19+J19),"Paid",IF(AND(H19>0,H19<F19+G19),"Partial",IF(AND(H19=0,TODAY()>C19),"Overdue","Pending"))))
A20: =IF(18<=Tenure,18,"") | B20: =IF(18<=Tenure,C19,"") | C20: =IF(18<=Tenure,WORKDAY.INTL(EDATE(FirstPayDate,17)-1,1,1,ArmenianHolidays),"") | D20: =IF(18<=Tenure,IF(18=Tenure,C20-C19+1,C20-C19),"") | E20: =IF(18<=Tenure,O19,"") | F20: =IF(18<=Tenure,E20*D20*(AnnualRate/100),"") | G20: =IF(18<=Tenure,IF(18=Tenure,E20,EMI-F20),"") | H20: =IF(18<=Tenure,IFERROR(SUMIFS(Payments!$C:$C,Payments!$B:$B,A20),0),"") | I20: =IF(18<=Tenure,IFERROR(AGGREGATE(15,6,Payments!$A$3:$A$200/(Payments!$B$3:$B$200=A20),1),""),"") | J20: =IF(18<=Tenure,IF(H20=0,0,IF(AND(I20<>"",I20<>0,I20<C20),MIN(F20,MAX(0,H20-K20)-IFERROR(MIN(MAX(0,(MAX(0,H20-K20)-F20)/(1-MAX(0,C20-I20)*(AnnualRate/100))),E20,MAX(0,H20-K20)),0)),MIN(F20,MAX(0,H20-K20)))),"") | K20: =IF(18<=Tenure,IF(H20=0,0,MIN(E20,MAX(0,MAX(0,H20-K20)-L20))),"") | L20: =IF(18<=Tenure,MAX(0,F20+G20+J20-K20-L20-M20),"") | M20: =IF(18<=Tenure,IF(18=Tenure,0,MAX(0,E20-M20)),"") | N20: =IF(18>Tenure,"",IF(AND(H20>0,H20>=F20+G20+J20),"Paid",IF(AND(H20>0,H20<F20+G20),"Partial",IF(AND(H20=0,TODAY()>C20),"Overdue","Pending"))))
A21: =IF(19<=Tenure,19,"") | B21: =IF(19<=Tenure,C20,"") | C21: =IF(19<=Tenure,WORKDAY.INTL(EDATE(FirstPayDate,18)-1,1,1,ArmenianHolidays),"") | D21: =IF(19<=Tenure,IF(19=Tenure,C21-C20+1,C21-C20),"") | E21: =IF(19<=Tenure,O20,"") | F21: =IF(19<=Tenure,E21*D21*(AnnualRate/100),"") | G21: =IF(19<=Tenure,IF(19=Tenure,E21,EMI-F21),"") | H21: =IF(19<=Tenure,IFERROR(SUMIFS(Payments!$C:$C,Payments!$B:$B,A21),0),"") | I21: =IF(19<=Tenure,IFERROR(AGGREGATE(15,6,Payments!$A$3:$A$200/(Payments!$B$3:$B$200=A21),1),""),"") | J21: =IF(19<=Tenure,IF(H21=0,0,IF(AND(I21<>"",I21<>0,I21<C21),MIN(F21,MAX(0,H21-K21)-IFERROR(MIN(MAX(0,(MAX(0,H21-K21)-F21)/(1-MAX(0,C21-I21)*(AnnualRate/100))),E21,MAX(0,H21-K21)),0)),MIN(F21,MAX(0,H21-K21)))),"") | K21: =IF(19<=Tenure,IF(H21=0,0,MIN(E21,MAX(0,MAX(0,H21-K21)-L21))),"") | L21: =IF(19<=Tenure,MAX(0,F21+G21+J21-K21-L21-M21),"") | M21: =IF(19<=Tenure,IF(19=Tenure,0,MAX(0,E21-M21)),"") | N21: =IF(19>Tenure,"",IF(AND(H21>0,H21>=F21+G21+J21),"Paid",IF(AND(H21>0,H21<F21+G21),"Partial",IF(AND(H21=0,TODAY()>C21),"Overdue","Pending"))))
A22: =IF(20<=Tenure,20,"") | B22: =IF(20<=Tenure,C21,"") | C22: =IF(20<=Tenure,WORKDAY.INTL(EDATE(FirstPayDate,19)-1,1,1,ArmenianHolidays),"") | D22: =IF(20<=Tenure,IF(20=Tenure,C22-C21+1,C22-C21),"") | E22: =IF(20<=Tenure,O21,"") | F22: =IF(20<=Tenure,E22*D22*(AnnualRate/100),"") | G22: =IF(20<=Tenure,IF(20=Tenure,E22,EMI-F22),"") | H22: =IF(20<=Tenure,IFERROR(SUMIFS(Payments!$C:$C,Payments!$B:$B,A22),0),"") | I22: =IF(20<=Tenure,IFERROR(AGGREGATE(15,6,Payments!$A$3:$A$200/(Payments!$B$3:$B$200=A22),1),""),"") | J22: =IF(20<=Tenure,IF(H22=0,0,IF(AND(I22<>"",I22<>0,I22<C22),MIN(F22,MAX(0,H22-K22)-IFERROR(MIN(MAX(0,(MAX(0,H22-K22)-F22)/(1-MAX(0,C22-I22)*(AnnualRate/100))),E22,MAX(0,H22-K22)),0)),MIN(F22,MAX(0,H22-K22)))),"") | K22: =IF(20<=Tenure,IF(H22=0,0,MIN(E22,MAX(0,MAX(0,H22-K22)-L22))),"") | L22: =IF(20<=Tenure,MAX(0,F22+G22+J22-K22-L22-M22),"") | M22: =IF(20<=Tenure,IF(20=Tenure,0,MAX(0,E22-M22)),"") | N22: =IF(20>Tenure,"",IF(AND(H22>0,H22>=F22+G22+J22),"Paid",IF(AND(H22>0,H22<F22+G22),"Partial",IF(AND(H22=0,TODAY()>C22),"Overdue","Pending"))))
A23: =IF(21<=Tenure,21,"") | B23: =IF(21<=Tenure,C22,"") | C23: =IF(21<=Tenure,WORKDAY.INTL(EDATE(FirstPayDate,20)-1,1,1,ArmenianHolidays),"") | D23: =IF(21<=Tenure,IF(21=Tenure,C23-C22+1,C23-C22),"") | E23: =IF(21<=Tenure,O22,"") | F23: =IF(21<=Tenure,E23*D23*(AnnualRate/100),"") | G23: =IF(21<=Tenure,IF(21=Tenure,E23,EMI-F23),"") | H23: =IF(21<=Tenure,IFERROR(SUMIFS(Payments!$C:$C,Payments!$B:$B,A23),0),"") | I23: =IF(21<=Tenure,IFERROR(AGGREGATE(15,6,Payments!$A$3:$A$200/(Payments!$B$3:$B$200=A23),1),""),"") | J23: =IF(21<=Tenure,IF(H23=0,0,IF(AND(I23<>"",I23<>0,I23<C23),MIN(F23,MAX(0,H23-K23)-IFERROR(MIN(MAX(0,(MAX(0,H23-K23)-F23)/(1-MAX(0,C23-I23)*(AnnualRate/100))),E23,MAX(0,H23-K23)),0)),MIN(F23,MAX(0,H23-K23)))),"") | K23: =IF(21<=Tenure,IF(H23=0,0,MIN(E23,MAX(0,MAX(0,H23-K23)-L23))),"") | L23: =IF(21<=Tenure,MAX(0,F23+G23+J23-K23-L23-M23),"") | M23: =IF(21<=Tenure,IF(21=Tenure,0,MAX(0,E23-M23)),"") | N23: =IF(21>Tenure,"",IF(AND(H23>0,H23>=F23+G23+J23),"Paid",IF(AND(H23>0,H23<F23+G23),"Partial",IF(AND(H23=0,TODAY()>C23),"Overdue","Pending"))))
A24: =IF(22<=Tenure,22,"") | B24: =IF(22<=Tenure,C23,"") | C24: =IF(22<=Tenure,WORKDAY.INTL(EDATE(FirstPayDate,21)-1,1,1,ArmenianHolidays),"") | D24: =IF(22<=Tenure,IF(22=Tenure,C24-C23+1,C24-C23),"") | E24: =IF(22<=Tenure,O23,"") | F24: =IF(22<=Tenure,E24*D24*(AnnualRate/100),"") | G24: =IF(22<=Tenure,IF(22=Tenure,E24,EMI-F24),"") | H24: =IF(22<=Tenure,IFERROR(SUMIFS(Payments!$C:$C,Payments!$B:$B,A24),0),"") | I24: =IF(22<=Tenure,IFERROR(AGGREGATE(15,6,Payments!$A$3:$A$200/(Payments!$B$3:$B$200=A24),1),""),"") | J24: =IF(22<=Tenure,IF(H24=0,0,IF(AND(I24<>"",I24<>0,I24<C24),MIN(F24,MAX(0,H24-K24)-IFERROR(MIN(MAX(0,(MAX(0,H24-K24)-F24)/(1-MAX(0,C24-I24)*(AnnualRate/100))),E24,MAX(0,H24-K24)),0)),MIN(F24,MAX(0,H24-K24)))),"") | K24: =IF(22<=Tenure,IF(H24=0,0,MIN(E24,MAX(0,MAX(0,H24-K24)-L24))),"") | L24: =IF(22<=Tenure,MAX(0,F24+G24+J24-K24-L24-M24),"") | M24: =IF(22<=Tenure,IF(22=Tenure,0,MAX(0,E24-M24)),"") | N24: =IF(22>Tenure,"",IF(AND(H24>0,H24>=F24+G24+J24),"Paid",IF(AND(H24>0,H24<F24+G24),"Partial",IF(AND(H24=0,TODAY()>C24),"Overdue","Pending"))))
A25: =IF(23<=Tenure,23,"") | B25: =IF(23<=Tenure,C24,"") | C25: =IF(23<=Tenure,WORKDAY.INTL(EDATE(FirstPayDate,22)-1,1,1,ArmenianHolidays),"") | D25: =IF(23<=Tenure,IF(23=Tenure,C25-C24+1,C25-C24),"") | E25: =IF(23<=Tenure,O24,"") | F25: =IF(23<=Tenure,E25*D25*(AnnualRate/100),"") | G25: =IF(23<=Tenure,IF(23=Tenure,E25,EMI-F25),"") | H25: =IF(23<=Tenure,IFERROR(SUMIFS(Payments!$C:$C,Payments!$B:$B,A25),0),"") | I25: =IF(23<=Tenure,IFERROR(AGGREGATE(15,6,Payments!$A$3:$A$200/(Payments!$B$3:$B$200=A25),1),""),"") | J25: =IF(23<=Tenure,IF(H25=0,0,IF(AND(I25<>"",I25<>0,I25<C25),MIN(F25,MAX(0,H25-K25)-IFERROR(MIN(MAX(0,(MAX(0,H25-K25)-F25)/(1-MAX(0,C25-I25)*(AnnualRate/100))),E25,MAX(0,H25-K25)),0)),MIN(F25,MAX(0,H25-K25)))),"") | K25: =IF(23<=Tenure,IF(H25=0,0,MIN(E25,MAX(0,MAX(0,H25-K25)-L25))),"") | L25: =IF(23<=Tenure,MAX(0,F25+G25+J25-K25-L25-M25),"") | M25: =IF(23<=Tenure,IF(23=Tenure,0,MAX(0,E25-M25)),"") | N25: =IF(23>Tenure,"",IF(AND(H25>0,H25>=F25+G25+J25),"Paid",IF(AND(H25>0,H25<F25+G25),"Partial",IF(AND(H25=0,TODAY()>C25),"Overdue","Pending"))))
A26: =IF(24<=Tenure,24,"") | B26: =IF(24<=Tenure,C25,"") | C26: =IF(24<=Tenure,WORKDAY.INTL(EDATE(FirstPayDate,23)-1,1,1,ArmenianHolidays),"") | D26: =IF(24<=Tenure,IF(24=Tenure,C26-C25+1,C26-C25),"") | E26: =IF(24<=Tenure,O25,"") | F26: =IF(24<=Tenure,E26*D26*(AnnualRate/100),"") | G26: =IF(24<=Tenure,IF(24=Tenure,E26,EMI-F26),"") | H26: =IF(24<=Tenure,IFERROR(SUMIFS(Payments!$C:$C,Payments!$B:$B,A26),0),"") | I26: =IF(24<=Tenure,IFERROR(AGGREGATE(15,6,Payments!$A$3:$A$200/(Payments!$B$3:$B$200=A26),1),""),"") | J26: =IF(24<=Tenure,IF(H26=0,0,IF(AND(I26<>"",I26<>0,I26<C26),MIN(F26,MAX(0,H26-K26)-IFERROR(MIN(MAX(0,(MAX(0,H26-K26)-F26)/(1-MAX(0,C26-I26)*(AnnualRate/100))),E26,MAX(0,H26-K26)),0)),MIN(F26,MAX(0,H26-K26)))),"") | K26: =IF(24<=Tenure,IF(H26=0,0,MIN(E26,MAX(0,MAX(0,H26-K26)-L26))),"") | L26: =IF(24<=Tenure,MAX(0,F26+G26+J26-K26-L26-M26),"") | M26: =IF(24<=Tenure,IF(24=Tenure,0,MAX(0,E26-M26)),"") | N26: =IF(24>Tenure,"",IF(AND(H26>0,H26>=F26+G26+J26),"Paid",IF(AND(H26>0,H26<F26+G26),"Partial",IF(AND(H26=0,TODAY()>C26),"Overdue","Pending"))))
A27: =IF(25<=Tenure,25,"") | B27: =IF(25<=Tenure,C26,"") | C27: =IF(25<=Tenure,WORKDAY.INTL(EDATE(FirstPayDate,24)-1,1,1,ArmenianHolidays),"") | D27: =IF(25<=Tenure,IF(25=Tenure,C27-C26+1,C27-C26),"") | E27: =IF(25<=Tenure,O26,"") | F27: =IF(25<=Tenure,E27*D27*(AnnualRate/100),"") | G27: =IF(25<=Tenure,IF(25=Tenure,E27,EMI-F27),"") | H27: =IF(25<=Tenure,IFERROR(SUMIFS(Payments!$C:$C,Payments!$B:$B,A27),0),"") | I27: =IF(25<=Tenure,IFERROR(AGGREGATE(15,6,Payments!$A$3:$A$200/(Payments!$B$3:$B$200=A27),1),""),"") | J27: =IF(25<=Tenure,IF(H27=0,0,IF(AND(I27<>"",I27<>0,I27<C27),MIN(F27,MAX(0,H27-K27)-IFERROR(MIN(MAX(0,(MAX(0,H27-K27)-F27)/(1-MAX(0,C27-I27)*(AnnualRate/100))),E27,MAX(0,H27-K27)),0)),MIN(F27,MAX(0,H27-K27)))),"") | K27: =IF(25<=Tenure,IF(H27=0,0,MIN(E27,MAX(0,MAX(0,H27-K27)-L27))),"") | L27: =IF(25<=Tenure,MAX(0,F27+G27+J27-K27-L27-M27),"") | M27: =IF(25<=Tenure,IF(25=Tenure,0,MAX(0,E27-M27)),"") | N27: =IF(25>Tenure,"",IF(AND(H27>0,H27>=F27+G27+J27),"Paid",IF(AND(H27>0,H27<F27+G27),"Partial",IF(AND(H27=0,TODAY()>C27),"Overdue","Pending"))))
A28: =IF(26<=Tenure,26,"") | B28: =IF(26<=Tenure,C27,"") | C28: =IF(26<=Tenure,WORKDAY.INTL(EDATE(FirstPayDate,25)-1,1,1,ArmenianHolidays),"") | D28: =IF(26<=Tenure,IF(26=Tenure,C28-C27+1,C28-C27),"") | E28: =IF(26<=Tenure,O27,"") | F28: =IF(26<=Tenure,E28*D28*(AnnualRate/100),"") | G28: =IF(26<=Tenure,IF(26=Tenure,E28,EMI-F28),"") | H28: =IF(26<=Tenure,IFERROR(SUMIFS(Payments!$C:$C,Payments!$B:$B,A28),0),"") | I28: =IF(26<=Tenure,IFERROR(AGGREGATE(15,6,Payments!$A$3:$A$200/(Payments!$B$3:$B$200=A28),1),""),"") | J28: =IF(26<=Tenure,IF(H28=0,0,IF(AND(I28<>"",I28<>0,I28<C28),MIN(F28,MAX(0,H28-K28)-IFERROR(MIN(MAX(0,(MAX(0,H28-K28)-F28)/(1-MAX(0,C28-I28)*(AnnualRate/100))),E28,MAX(0,H28-K28)),0)),MIN(F28,MAX(0,H28-K28)))),"") | K28: =IF(26<=Tenure,IF(H28=0,0,MIN(E28,MAX(0,MAX(0,H28-K28)-L28))),"") | L28: =IF(26<=Tenure,MAX(0,F28+G28+J28-K28-L28-M28),"") | M28: =IF(26<=Tenure,IF(26=Tenure,0,MAX(0,E28-M28)),"") | N28: =IF(26>Tenure,"",IF(AND(H28>0,H28>=F28+G28+J28),"Paid",IF(AND(H28>0,H28<F28+G28),"Partial",IF(AND(H28=0,TODAY()>C28),"Overdue","Pending"))))
A29: =IF(27<=Tenure,27,"") | B29: =IF(27<=Tenure,C28,"") | C29: =IF(27<=Tenure,WORKDAY.INTL(EDATE(FirstPayDate,26)-1,1,1,ArmenianHolidays),"") | D29: =IF(27<=Tenure,IF(27=Tenure,C29-C28+1,C29-C28),"") | E29: =IF(27<=Tenure,O28,"") | F29: =IF(27<=Tenure,E29*D29*(AnnualRate/100),"") | G29: =IF(27<=Tenure,IF(27=Tenure,E29,EMI-F29),"") | H29: =IF(27<=Tenure,IFERROR(SUMIFS(Payments!$C:$C,Payments!$B:$B,A29),0),"") | I29: =IF(27<=Tenure,IFERROR(AGGREGATE(15,6,Payments!$A$3:$A$200/(Payments!$B$3:$B$200=A29),1),""),"") | J29: =IF(27<=Tenure,IF(H29=0,0,IF(AND(I29<>"",I29<>0,I29<C29),MIN(F29,MAX(0,H29-K29)-IFERROR(MIN(MAX(0,(MAX(0,H29-K29)-F29)/(1-MAX(0,C29-I29)*(AnnualRate/100))),E29,MAX(0,H29-K29)),0)),MIN(F29,MAX(0,H29-K29)))),"") | K29: =IF(27<=Tenure,IF(H29=0,0,MIN(E29,MAX(0,MAX(0,H29-K29)-L29))),"") | L29: =IF(27<=Tenure,MAX(0,F29+G29+J29-K29-L29-M29),"") | M29: =IF(27<=Tenure,IF(27=Tenure,0,MAX(0,E29-M29)),"") | N29: =IF(27>Tenure,"",IF(AND(H29>0,H29>=F29+G29+J29),"Paid",IF(AND(H29>0,H29<F29+G29),"Partial",IF(AND(H29=0,TODAY()>C29),"Overdue","Pending"))))
A30: =IF(28<=Tenure,28,"") | B30: =IF(28<=Tenure,C29,"") | C30: =IF(28<=Tenure,WORKDAY.INTL(EDATE(FirstPayDate,27)-1,1,1,ArmenianHolidays),"") | D30: =IF(28<=Tenure,IF(28=Tenure,C30-C29+1,C30-C29),"") | E30: =IF(28<=Tenure,O29,"") | F30: =IF(28<=Tenure,E30*D30*(AnnualRate/100),"") | G30: =IF(28<=Tenure,IF(28=Tenure,E30,EMI-F30),"") | H30: =IF(28<=Tenure,IFERROR(SUMIFS(Payments!$C:$C,Payments!$B:$B,A30),0),"") | I30: =IF(28<=Tenure,IFERROR(AGGREGATE(15,6,Payments!$A$3:$A$200/(Payments!$B$3:$B$200=A30),1),""),"") | J30: =IF(28<=Tenure,IF(H30=0,0,IF(AND(I30<>"",I30<>0,I30<C30),MIN(F30,MAX(0,H30-K30)-IFERROR(MIN(MAX(0,(MAX(0,H30-K30)-F30)/(1-MAX(0,C30-I30)*(AnnualRate/100))),E30,MAX(0,H30-K30)),0)),MIN(F30,MAX(0,H30-K30)))),"") | K30: =IF(28<=Tenure,IF(H30=0,0,MIN(E30,MAX(0,MAX(0,H30-K30)-L30))),"") | L30: =IF(28<=Tenure,MAX(0,F30+G30+J30-K30-L30-M30),"") | M30: =IF(28<=Tenure,IF(28=Tenure,0,MAX(0,E30-M30)),"") | N30: =IF(28>Tenure,"",IF(AND(H30>0,H30>=F30+G30+J30),"Paid",IF(AND(H30>0,H30<F30+G30),"Partial",IF(AND(H30=0,TODAY()>C30),"Overdue","Pending"))))
A31: =IF(29<=Tenure,29,"") | B31: =IF(29<=Tenure,C30,"") | C31: =IF(29<=Tenure,WORKDAY.INTL(EDATE(FirstPayDate,28)-1,1,1,ArmenianHolidays),"") | D31: =IF(29<=Tenure,IF(29=Tenure,C31-C30+1,C31-C30),"") | E31: =IF(29<=Tenure,O30,"") | F31: =IF(29<=Tenure,E31*D31*(AnnualRate/100),"") | G31: =IF(29<=Tenure,IF(29=Tenure,E31,EMI-F31),"") | H31: =IF(29<=Tenure,IFERROR(SUMIFS(Payments!$C:$C,Payments!$B:$B,A31),0),"") | I31: =IF(29<=Tenure,IFERROR(AGGREGATE(15,6,Payments!$A$3:$A$200/(Payments!$B$3:$B$200=A31),1),""),"") | J31: =IF(29<=Tenure,IF(H31=0,0,IF(AND(I31<>"",I31<>0,I31<C31),MIN(F31,MAX(0,H31-K31)-IFERROR(MIN(MAX(0,(MAX(0,H31-K31)-F31)/(1-MAX(0,C31-I31)*(AnnualRate/100))),E31,MAX(0,H31-K31)),0)),MIN(F31,MAX(0,H31-K31)))),"") | K31: =IF(29<=Tenure,IF(H31=0,0,MIN(E31,MAX(0,MAX(0,H31-K31)-L31))),"") | L31: =IF(29<=Tenure,MAX(0,F31+G31+J31-K31-L31-M31),"") | M31: =IF(29<=Tenure,IF(29=Tenure,0,MAX(0,E31-M31)),"") | N31: =IF(29>Tenure,"",IF(AND(H31>0,H31>=F31+G31+J31),"Paid",IF(AND(H31>0,H31<F31+G31),"Partial",IF(AND(H31=0,TODAY()>C31),"Overdue","Pending"))))
A32: =IF(30<=Tenure,30,"") | B32: =IF(30<=Tenure,C31,"") | C32: =IF(30<=Tenure,WORKDAY.INTL(EDATE(FirstPayDate,29)-1,1,1,ArmenianHolidays),"") | D32: =IF(30<=Tenure,IF(30=Tenure,C32-C31+1,C32-C31),"") | E32: =IF(30<=Tenure,O31,"") | F32: =IF(30<=Tenure,E32*D32*(AnnualRate/100),"") | G32: =IF(30<=Tenure,IF(30=Tenure,E32,EMI-F32),"") | H32: =IF(30<=Tenure,IFERROR(SUMIFS(Payments!$C:$C,Payments!$B:$B,A32),0),"") | I32: =IF(30<=Tenure,IFERROR(AGGREGATE(15,6,Payments!$A$3:$A$200/(Payments!$B$3:$B$200=A32),1),""),"") | J32: =IF(30<=Tenure,IF(H32=0,0,IF(AND(I32<>"",I32<>0,I32<C32),MIN(F32,MAX(0,H32-K32)-IFERROR(MIN(MAX(0,(MAX(0,H32-K32)-F32)/(1-MAX(0,C32-I32)*(AnnualRate/100))),E32,MAX(0,H32-K32)),0)),MIN(F32,MAX(0,H32-K32)))),"") | K32: =IF(30<=Tenure,IF(H32=0,0,MIN(E32,MAX(0,MAX(0,H32-K32)-L32))),"") | L32: =IF(30<=Tenure,MAX(0,F32+G32+J32-K32-L32-M32),"") | M32: =IF(30<=Tenure,IF(30=Tenure,0,MAX(0,E32-M32)),"") | N32: =IF(30>Tenure,"",IF(AND(H32>0,H32>=F32+G32+J32),"Paid",IF(AND(H32>0,H32<F32+G32),"Partial",IF(AND(H32=0,TODAY()>C32),"Overdue","Pending"))))
A33: =IF(31<=Tenure,31,"") | B33: =IF(31<=Tenure,C32,"") | C33: =IF(31<=Tenure,WORKDAY.INTL(EDATE(FirstPayDate,30)-1,1,1,ArmenianHolidays),"") | D33: =IF(31<=Tenure,IF(31=Tenure,C33-C32+1,C33-C32),"") | E33: =IF(31<=Tenure,O32,"") | F33: =IF(31<=Tenure,E33*D33*(AnnualRate/100),"") | G33: =IF(31<=Tenure,IF(31=Tenure,E33,EMI-F33),"") | H33: =IF(31<=Tenure,IFERROR(SUMIFS(Payments!$C:$C,Payments!$B:$B,A33),0),"") | I33: =IF(31<=Tenure,IFERROR(AGGREGATE(15,6,Payments!$A$3:$A$200/(Payments!$B$3:$B$200=A33),1),""),"") | J33: =IF(31<=Tenure,IF(H33=0,0,IF(AND(I33<>"",I33<>0,I33<C33),MIN(F33,MAX(0,H33-K33)-IFERROR(MIN(MAX(0,(MAX(0,H33-K33)-F33)/(1-MAX(0,C33-I33)*(AnnualRate/100))),E33,MAX(0,H33-K33)),0)),MIN(F33,MAX(0,H33-K33)))),"") | K33: =IF(31<=Tenure,IF(H33=0,0,MIN(E33,MAX(0,MAX(0,H33-K33)-L33))),"") | L33: =IF(31<=Tenure,MAX(0,F33+G33+J33-K33-L33-M33),"") | M33: =IF(31<=Tenure,IF(31=Tenure,0,MAX(0,E33-M33)),"") | N33: =IF(31>Tenure,"",IF(AND(H33>0,H33>=F33+G33+J33),"Paid",IF(AND(H33>0,H33<F33+G33),"Partial",IF(AND(H33=0,TODAY()>C33),"Overdue","Pending"))))
A34: =IF(32<=Tenure,32,"") | B34: =IF(32<=Tenure,C33,"") | C34: =IF(32<=Tenure,WORKDAY.INTL(EDATE(FirstPayDate,31)-1,1,1,ArmenianHolidays),"") | D34: =IF(32<=Tenure,IF(32=Tenure,C34-C33+1,C34-C33),"") | E34: =IF(32<=Tenure,O33,"") | F34: =IF(32<=Tenure,E34*D34*(AnnualRate/100),"") | G34: =IF(32<=Tenure,IF(32=Tenure,E34,EMI-F34),"") | H34: =IF(32<=Tenure,IFERROR(SUMIFS(Payments!$C:$C,Payments!$B:$B,A34),0),"") | I34: =IF(32<=Tenure,IFERROR(AGGREGATE(15,6,Payments!$A$3:$A$200/(Payments!$B$3:$B$200=A34),1),""),"") | J34: =IF(32<=Tenure,IF(H34=0,0,IF(AND(I34<>"",I34<>0,I34<C34),MIN(F34,MAX(0,H34-K34)-IFERROR(MIN(MAX(0,(MAX(0,H34-K34)-F34)/(1-MAX(0,C34-I34)*(AnnualRate/100))),E34,MAX(0,H34-K34)),0)),MIN(F34,MAX(0,H34-K34)))),"") | K34: =IF(32<=Tenure,IF(H34=0,0,MIN(E34,MAX(0,MAX(0,H34-K34)-L34))),"") | L34: =IF(32<=Tenure,MAX(0,F34+G34+J34-K34-L34-M34),"") | M34: =IF(32<=Tenure,IF(32=Tenure,0,MAX(0,E34-M34)),"") | N34: =IF(32>Tenure,"",IF(AND(H34>0,H34>=F34+G34+J34),"Paid",IF(AND(H34>0,H34<F34+G34),"Partial",IF(AND(H34=0,TODAY()>C34),"Overdue","Pending"))))
A35: =IF(33<=Tenure,33,"") | B35: =IF(33<=Tenure,C34,"") | C35: =IF(33<=Tenure,WORKDAY.INTL(EDATE(FirstPayDate,32)-1,1,1,ArmenianHolidays),"") | D35: =IF(33<=Tenure,IF(33=Tenure,C35-C34+1,C35-C34),"") | E35: =IF(33<=Tenure,O34,"") | F35: =IF(33<=Tenure,E35*D35*(AnnualRate/100),"") | G35: =IF(33<=Tenure,IF(33=Tenure,E35,EMI-F35),"") | H35: =IF(33<=Tenure,IFERROR(SUMIFS(Payments!$C:$C,Payments!$B:$B,A35),0),"") | I35: =IF(33<=Tenure,IFERROR(AGGREGATE(15,6,Payments!$A$3:$A$200/(Payments!$B$3:$B$200=A35),1),""),"") | J35: =IF(33<=Tenure,IF(H35=0,0,IF(AND(I35<>"",I35<>0,I35<C35),MIN(F35,MAX(0,H35-K35)-IFERROR(MIN(MAX(0,(MAX(0,H35-K35)-F35)/(1-MAX(0,C35-I35)*(AnnualRate/100))),E35,MAX(0,H35-K35)),0)),MIN(F35,MAX(0,H35-K35)))),"") | K35: =IF(33<=Tenure,IF(H35=0,0,MIN(E35,MAX(0,MAX(0,H35-K35)-L35))),"") | L35: =IF(33<=Tenure,MAX(0,F35+G35+J35-K35-L35-M35),"") | M35: =IF(33<=Tenure,IF(33=Tenure,0,MAX(0,E35-M35)),"") | N35: =IF(33>Tenure,"",IF(AND(H35>0,H35>=F35+G35+J35),"Paid",IF(AND(H35>0,H35<F35+G35),"Partial",IF(AND(H35=0,TODAY()>C35),"Overdue","Pending"))))
A36: =IF(34<=Tenure,34,"") | B36: =IF(34<=Tenure,C35,"") | C36: =IF(34<=Tenure,WORKDAY.INTL(EDATE(FirstPayDate,33)-1,1,1,ArmenianHolidays),"") | D36: =IF(34<=Tenure,IF(34=Tenure,C36-C35+1,C36-C35),"") | E36: =IF(34<=Tenure,O35,"") | F36: =IF(34<=Tenure,E36*D36*(AnnualRate/100),"") | G36: =IF(34<=Tenure,IF(34=Tenure,E36,EMI-F36),"") | H36: =IF(34<=Tenure,IFERROR(SUMIFS(Payments!$C:$C,Payments!$B:$B,A36),0),"") | I36: =IF(34<=Tenure,IFERROR(AGGREGATE(15,6,Payments!$A$3:$A$200/(Payments!$B$3:$B$200=A36),1),""),"") | J36: =IF(34<=Tenure,IF(H36=0,0,IF(AND(I36<>"",I36<>0,I36<C36),MIN(F36,MAX(0,H36-K36)-IFERROR(MIN(MAX(0,(MAX(0,H36-K36)-F36)/(1-MAX(0,C36-I36)*(AnnualRate/100))),E36,MAX(0,H36-K36)),0)),MIN(F36,MAX(0,H36-K36)))),"") | K36: =IF(34<=Tenure,IF(H36=0,0,MIN(E36,MAX(0,MAX(0,H36-K36)-L36))),"") | L36: =IF(34<=Tenure,MAX(0,F36+G36+J36-K36-L36-M36),"") | M36: =IF(34<=Tenure,IF(34=Tenure,0,MAX(0,E36-M36)),"") | N36: =IF(34>Tenure,"",IF(AND(H36>0,H36>=F36+G36+J36),"Paid",IF(AND(H36>0,H36<F36+G36),"Partial",IF(AND(H36=0,TODAY()>C36),"Overdue","Pending"))))
A37: =IF(35<=Tenure,35,"") | B37: =IF(35<=Tenure,C36,"") | C37: =IF(35<=Tenure,WORKDAY.INTL(EDATE(FirstPayDate,34)-1,1,1,ArmenianHolidays),"") | D37: =IF(35<=Tenure,IF(35=Tenure,C37-C36+1,C37-C36),"") | E37: =IF(35<=Tenure,O36,"") | F37: =IF(35<=Tenure,E37*D37*(AnnualRate/100),"") | G37: =IF(35<=Tenure,IF(35=Tenure,E37,EMI-F37),"") | H37: =IF(35<=Tenure,IFERROR(SUMIFS(Payments!$C:$C,Payments!$B:$B,A37),0),"") | I37: =IF(35<=Tenure,IFERROR(AGGREGATE(15,6,Payments!$A$3:$A$200/(Payments!$B$3:$B$200=A37),1),""),"") | J37: =IF(35<=Tenure,IF(H37=0,0,IF(AND(I37<>"",I37<>0,I37<C37),MIN(F37,MAX(0,H37-K37)-IFERROR(MIN(MAX(0,(MAX(0,H37-K37)-F37)/(1-MAX(0,C37-I37)*(AnnualRate/100))),E37,MAX(0,H37-K37)),0)),MIN(F37,MAX(0,H37-K37)))),"") | K37: =IF(35<=Tenure,IF(H37=0,0,MIN(E37,MAX(0,MAX(0,H37-K37)-L37))),"") | L37: =IF(35<=Tenure,MAX(0,F37+G37+J37-K37-L37-M37),"") | M37: =IF(35<=Tenure,IF(35=Tenure,0,MAX(0,E37-M37)),"") | N37: =IF(35>Tenure,"",IF(AND(H37>0,H37>=F37+G37+J37),"Paid",IF(AND(H37>0,H37<F37+G37),"Partial",IF(AND(H37=0,TODAY()>C37),"Overdue","Pending"))))
A38: =IF(36<=Tenure,36,"") | B38: =IF(36<=Tenure,C37,"") | C38: =IF(36<=Tenure,WORKDAY.INTL(EDATE(FirstPayDate,35)-1,1,1,ArmenianHolidays),"") | D38: =IF(36<=Tenure,IF(36=Tenure,C38-C37+1,C38-C37),"") | E38: =IF(36<=Tenure,O37,"") | F38: =IF(36<=Tenure,E38*D38*(AnnualRate/100),"") | G38: =IF(36<=Tenure,IF(36=Tenure,E38,EMI-F38),"") | H38: =IF(36<=Tenure,IFERROR(SUMIFS(Payments!$C:$C,Payments!$B:$B,A38),0),"") | I38: =IF(36<=Tenure,IFERROR(AGGREGATE(15,6,Payments!$A$3:$A$200/(Payments!$B$3:$B$200=A38),1),""),"") | J38: =IF(36<=Tenure,IF(H38=0,0,IF(AND(I38<>"",I38<>0,I38<C38),MIN(F38,MAX(0,H38-K38)-IFERROR(MIN(MAX(0,(MAX(0,H38-K38)-F38)/(1-MAX(0,C38-I38)*(AnnualRate/100))),E38,MAX(0,H38-K38)),0)),MIN(F38,MAX(0,H38-K38)))),"") | K38: =IF(36<=Tenure,IF(H38=0,0,MIN(E38,MAX(0,MAX(0,H38-K38)-L38))),"") | L38: =IF(36<=Tenure,MAX(0,F38+G38+J38-K38-L38-M38),"") | M38: =IF(36<=Tenure,IF(36=Tenure,0,MAX(0,E38-M38)),"") | N38: =IF(36>Tenure,"",IF(AND(H38>0,H38>=F38+G38+J38),"Paid",IF(AND(H38>0,H38<F38+G38),"Partial",IF(AND(H38=0,TODAY()>C38),"Overdue","Pending"))))
A39: =IF(37<=Tenure,37,"") | B39: =IF(37<=Tenure,C38,"") | C39: =IF(37<=Tenure,WORKDAY.INTL(EDATE(FirstPayDate,36)-1,1,1,ArmenianHolidays),"") | D39: =IF(37<=Tenure,IF(37=Tenure,C39-C38+1,C39-C38),"") | E39: =IF(37<=Tenure,O38,"") | F39: =IF(37<=Tenure,E39*D39*(AnnualRate/100),"") | G39: =IF(37<=Tenure,IF(37=Tenure,E39,EMI-F39),"") | H39: =IF(37<=Tenure,IFERROR(SUMIFS(Payments!$C:$C,Payments!$B:$B,A39),0),"") | I39: =IF(37<=Tenure,IFERROR(AGGREGATE(15,6,Payments!$A$3:$A$200/(Payments!$B$3:$B$200=A39),1),""),"") | J39: =IF(37<=Tenure,IF(H39=0,0,IF(AND(I39<>"",I39<>0,I39<C39),MIN(F39,MAX(0,H39-K39)-IFERROR(MIN(MAX(0,(MAX(0,H39-K39)-F39)/(1-MAX(0,C39-I39)*(AnnualRate/100))),E39,MAX(0,H39-K39)),0)),MIN(F39,MAX(0,H39-K39)))),"") | K39: =IF(37<=Tenure,IF(H39=0,0,MIN(E39,MAX(0,MAX(0,H39-K39)-L39))),"") | L39: =IF(37<=Tenure,MAX(0,F39+G39+J39-K39-L39-M39),"") | M39: =IF(37<=Tenure,IF(37=Tenure,0,MAX(0,E39-M39)),"") | N39: =IF(37>Tenure,"",IF(AND(H39>0,H39>=F39+G39+J39),"Paid",IF(AND(H39>0,H39<F39+G39),"Partial",IF(AND(H39=0,TODAY()>C39),"Overdue","Pending"))))
A40: =IF(38<=Tenure,38,"") | B40: =IF(38<=Tenure,C39,"") | C40: =IF(38<=Tenure,WORKDAY.INTL(EDATE(FirstPayDate,37)-1,1,1,ArmenianHolidays),"") | D40: =IF(38<=Tenure,IF(38=Tenure,C40-C39+1,C40-C39),"") | E40: =IF(38<=Tenure,O39,"") | F40: =IF(38<=Tenure,E40*D40*(AnnualRate/100),"") | G40: =IF(38<=Tenure,IF(38=Tenure,E40,EMI-F40),"") | H40: =IF(38<=Tenure,IFERROR(SUMIFS(Payments!$C:$C,Payments!$B:$B,A40),0),"") | I40: =IF(38<=Tenure,IFERROR(AGGREGATE(15,6,Payments!$A$3:$A$200/(Payments!$B$3:$B$200=A40),1),""),"") | J40: =IF(38<=Tenure,IF(H40=0,0,IF(AND(I40<>"",I40<>0,I40<C40),MIN(F40,MAX(0,H40-K40)-IFERROR(MIN(MAX(0,(MAX(0,H40-K40)-F40)/(1-MAX(0,C40-I40)*(AnnualRate/100))),E40,MAX(0,H40-K40)),0)),MIN(F40,MAX(0,H40-K40)))),"") | K40: =IF(38<=Tenure,IF(H40=0,0,MIN(E40,MAX(0,MAX(0,H40-K40)-L40))),"") | L40: =IF(38<=Tenure,MAX(0,F40+G40+J40-K40-L40-M40),"") | M40: =IF(38<=Tenure,IF(38=Tenure,0,MAX(0,E40-M40)),"") | N40: =IF(38>Tenure,"",IF(AND(H40>0,H40>=F40+G40+J40),"Paid",IF(AND(H40>0,H40<F40+G40),"Partial",IF(AND(H40=0,TODAY()>C40),"Overdue","Pending"))))
...

Sheet Payments
A1: PAYMENT ENTRY TABLE
A2: Payment Date | B2: Installment # | C2: Amount | D2: Notes | E2: Allocation Check
A3: 45703 | C3: =EMI | D3: On-time month 1 | E3: =IFERROR("Pen: "&TEXT(VLOOKUP(B3,Schedule!$A:$P,11,0),"#,##0.000")&" | Int: "&TEXT(VLOOKUP(B3,Schedule!$A:$P,12,0),"#,##0.000")&" | Prin: "&TEXT(VLOOKUP(B3,Schedule!$A:$P,13,0),"#,##0.000"),"")
A4: 45736 | C4: =EMI/2 | D4: Partial — 50% — 5 days late | E4: =IFERROR("Pen: "&TEXT(VLOOKUP(B4,Schedule!$A:$P,11,0),"#,##0.000")&" | Int: "&TEXT(VLOOKUP(B4,Schedule!$A:$P,12,0),"#,##0.000")&" | Prin: "&TEXT(VLOOKUP(B4,Schedule!$A:$P,13,0),"#,##0.000"),"")
A5: 45762 | C5: =EMI*2 | D5: Double payment — extra principal | E5: =IFERROR("Pen: "&TEXT(VLOOKUP(B5,Schedule!$A:$P,11,0),"#,##0.000")&" | Int: "&TEXT(VLOOKUP(B5,Schedule!$A:$P,12,0),"#,##0.000")&" | Prin: "&TEXT(VLOOKUP(B5,Schedule!$A:$P,13,0),"#,##0.000"),"")

Sheet Reconciliation
A1: RECONCILIATION DASHBOARD
A3: PRINCIPAL RECONCILIATION
A4: Metric | B4: Expected / Target | C4: =SUM(Schedule!$G$3:$G$62) | D4: Difference / Check
A5: Original Loan Amount | B5: =LoanAmount | C5: =SUM(Schedule!$M$3:$M$62) | D5: =B4-C4
A6: Total Principal Paid | B6: =LoanAmount-SUM(Schedule!$M$3:$M$62) | C6: =IFERROR(SUMIF(Schedule!$P$3:$P$62,"<>Paid",Schedule!$G$3:$G$62),0) | D6: =B5-C5
A7: Outstanding Principal | B7: =LoanAmount-SUM(Schedule!$M$3:$M$62) | C7: =IFERROR(INDEX(Schedule!$O$3:$O$62,MATCH(TRUE,Schedule!$O$3:$O$62<>"",0)+COUNTIF(Schedule!$A$3:$A$62,"<="&Tenure)-1),0) | D7: =IF(ABS(B6-C6)<1,"OK ✓","DISCREPANCY ✗")
A9: INTEREST RECONCILIATION
A10: Metric | B10: Expected / Target | C10: =SUM(Schedule!$F$3:$F$62) | D10: Difference / Check
A11: Total Interest Expected | B11: =Inputs!B19 | C11: =SUM(Schedule!$L$3:$L$62) | D11: =B10-C10
A12: Total Interest Paid | B12: =SUM(Schedule!$F$3:$F$62)-SUM(Schedule!$L$3:$L$62) | C12: =SUMIF(Schedule!$P$3:$P$62,"<>Paid",Schedule!$F$3:$F$62) | D12: =B11-C11
A13: Outstanding Interest | B13: =SUM(Schedule!$F$3:$F$62)-SUM(Schedule!$L$3:$L$62) | C13: =SUMIF(Schedule!$P$3:$P$62,"<>Paid",Schedule!$F$3:$F$62) | D13: =IF(ABS(B12-C12)<1,"OK ✓","DISCREPANCY ✗")
A16: Metric | B16: =SUM(Schedule!$J$3:$J$62) | C16: =SUM(Schedule!$J$3:$J$62) | D16: Difference / Check
A17: Total Penalties Assessed | B17: =SUM(Schedule!$K$3:$K$62) | C17: =SUM(Schedule!$K$3:$K$62) | D17: =B16-C16
A18: Total Penalties Paid | B18: =SUM(Schedule!$K$3:$K$62) | C18: =SUM(Schedule!$K$3:$K$62) | D18: =B17-C17
A19: Outstanding Penalties | B19: =B16-B17 | C19: =C16-C17 | D19: =IF(ABS(B18-C18)<0.001,"OK ✓","DISCREPANCY ✗")
A21: OVERALL SUMMARY
A22: Metric | B22: Expected / Target | C22: Actual (from schedule) | D22: Difference / Check
A23: Total EMI Scheduled | B23: =SUM(Payments!$C$3:$C$200) | C23: =SUM(Schedule!$H$3:$H$62) | D23: =B22-C22
A24: Total Cash Received | B24: =MAX(Schedule!$O$3:$O$62) | C24: =LoanAmount-SUM(Schedule!$M$3:$M$62) | D24: =IF(ABS(B23-C23)<0.001,"OK ✓","MATCH ✓")
A25: Current Outstanding Balance | B25: =MAX(Schedule!$O$3:$O$62) | C25: =LoanAmount-SUM(Schedule!$M$3:$M$62) | D25: =IF(ABS(B24-C24)<1,"BALANCED ✓","DISCREPANCY ✗")
A26: Overdue Installments | B26: =COUNTIF(Schedule!$P$3:$P$62,"Overdue") | C26: =COUNTIF(Schedule!$P$3:$P$62,"Partial") | D26: Overdue | Partial
