Workbook
Name Company: Sheet1!$D$10
Name CurrCode_ref: Sheet7!$R$6:$R$184
Name Date1: Sheet1!$D$11
Name Date2: Sheet1!$F$11
Name Loan_ref: Sheet7!$Q$6:$Q$9
Name LTV_ref: Sheet7!$T$6:$T$22
Name Name: Sheet1!$B$8
Name Norm_ref: Sheet7!$S$6:$S$7
Name x13V3_AmSinglBorR: Sheet1!$D$15
Name x13V3_MagnN3: Sheet1!$C$32
Name xV3_AddCapDedInc: Sheet2!$F$8
Name xV3_AddCapDedNotInc: Sheet2!$G$8
Name xV3_Cur_DailyVar: Sheet6!$B$9
Name xV3_Cur_Gold: Sheet5!$D$7
Name xV3_Cur_Long: Sheet5!$B$7
Name xV3_Cur_MaxPos: Sheet5!$E$7
Name xV3_Cur_RiskSt: Sheet5!$F$7
Name xV3_Cur_Short: Sheet5!$C$7
Name xV3_FixCapAmDed: Sheet2!$E$8
Name xV3_GrAddCap: Sheet2!$C$8
Name xV3_GrFixCap: Sheet2!$B$8
Name xV3_GrTotCap: Sheet2!$D$8
Name xV3_LTV_Loan_Curr: Sheet7!$C$5
Name xV3_LTV_Loan_N5: Sheet7!$D$5
Name xV3_LTV_Loan_Qt: Sheet7!$G$5
Name xV3_LTV_Loan_Ratio: Sheet7!$E$5
Name xV3_LTV_Loan_Sum: Sheet7!$F$5
Name xV3_LTV_Loan_Type: Sheet7!$B$5
Name xV3_NormAddCap: Sheet2!$J$8
Name xV3_NormFixCap: Sheet2!$H$8
Name xV3_NormGrAddCap: Sheet2!$I$8
Name xV3_NormTotCap: Sheet2!$K$8
Name xV3_RWA_OffBal: Sheet4!$Z$7
Name xV3_RWA_OffBalAss_R000: Sheet4!$B$7
Name xV3_RWA_OffBalAss_R010: Sheet4!$D$7
Name xV3_RWA_OffBalAss_R020: Sheet4!$F$7
Name xV3_RWA_OffBalAss_R030: Sheet4!$H$7
Name xV3_RWA_OffBalAss_R050: Sheet4!$J$7
Name xV3_RWA_OffBalAss_R075: Sheet4!$L$7
Name xV3_RWA_OffBalAss_R085: Sheet4!$N$7
Name xV3_RWA_OffBalAss_R100: Sheet4!$P$7
Name xV3_RWA_OffBalAss_R110: Sheet4!$R$7
Name xV3_RWA_OffBalAss_R125: Sheet4!$T$7
Name xV3_RWA_OffBalAss_R150: Sheet4!$V$7
Name xV3_RWA_OffBalAss_R225: Sheet4!$X$7
Name xV3_RWA_OffBalAss000Res: Sheet4!$C$7
Name xV3_RWA_OffBalAss010Res: Sheet4!$E$7
Name xV3_RWA_OffBalAss020Res: Sheet4!$G$7
Name xV3_RWA_OffBalAss030Res: Sheet4!$I$7
Name xV3_RWA_OffBalAss050Res: Sheet4!$K$7
Name xV3_RWA_OffBalAss075Res: Sheet4!$M$7
Name xV3_RWA_OffBalAss085Res: Sheet4!$O$7
Name xV3_RWA_OffBalAss100Res: Sheet4!$Q$7
Name xV3_RWA_OffBalAss110Res: Sheet4!$S$7
Name xV3_RWA_OffBalAss125Res: Sheet4!$U$7
Name xV3_RWA_OffBalAss150Res: Sheet4!$W$7
Name xV3_RWA_OffBalAss225Res: Sheet4!$Y$7
Name xV3_RWA_R000: Sheet3!$B$7
Name xV3_RWA_R010: Sheet3!$D$7
Name xV3_RWA_R020: Sheet3!$F$7

Sheet Sheet1
A1: 2026_June | I1: Ð²ìºÈì²Ì 2
F3: §ì³ñÏ³ÛÇÝ Ï³½Ù³Ï»ñåáõÃÛáõÝÝ»ñÇ Ñ³ßí»ïíáõÃÛáõÝÝ»ñÁ, ¹ñ³Ýó Ý»ñÏ³Û³óáõÙÁ ¨ Ññ³å³ñ³ÏáõÙÁ¦ Ï³ÝáÝ³Ï³ñ· 15-Ç
B7: Ð²ÞìºîìàôÂÚàôÜ | I7: Ò¨ ÃÇí 3
B8: ÐÇÙÝ³Ï³Ý ïÝï»ë³Ï³Ý ÝáñÙ³ïÇíÝ»ñÇ í»ñ³µ»ñÛ³É
C10: ì³ñÏ³ÛÇÝ Ï³½Ù³Ï»ñåáõÃÛ³Ý ³Ýí³ÝáõÙÁ
C11: ²Ùë³ÃÇíÁ | D11: 46054 | E11: Ã. -Çó ÙÇÝã¨ | F11: 46081 | G11: Ã.
E13: (Ñ³½. ¹ñ³Ù)
B14: ÀÝ¹Ñ³Ýáõñ Ï³åÇï³É | C14: èÇëÏáí Ïßéí³Í ³ÏïÇíÝ»ñ | D14: Ø»Ï ÷áË³éáõÇ ·Íáí éÇëÏÇ ·áõÙ³ñÁ | E14: ¶áñÍ³ÏÇó
B15: 1 | C15: 2 | D15: 3 | E15: 4
B16: =Sheet2!K40 -> 0 | C16: =Sheet3!Z39+Sheet4!Z39+E16*Sheet5!F39+E16*Sheet6!F10 -> 0
B30: Ü1 ÝáñÙ³ïÇíÇ Ù»ÍáõÃÛáõÝÁ | C30: Ü3 ÝáñÙ³ïÇíÇ Ù»ÍáõÃÛáõÝÁ
B32: (1/2) | C32: (3/1)
B33: =IF(C16=0,"",B16/C16) | C33: =D16/$B$16 -> #DIV/0!
C34: =D17/$B$16 -> #DIV/0!
C35: =D18/$B$16 -> #DIV/0!
C36: =D19/$B$16 -> #DIV/0!
C37: =D20/$B$16 -> #DIV/0!
C38: =D21/$B$16 -> #DIV/0!
C39: =D22/$B$16 -> #DIV/0!
C40: =D23/$B$16 -> #DIV/0!
C41: =D24/$B$16 -> #DIV/0!
C42: =D25/$B$16 -> #DIV/0!
C43: =D26/$B$16 -> #DIV/0!
C44: =D27/$B$16 -> #DIV/0!
C45: =D28/$B$16 -> #DIV/0!
F46: (Ñ³½. ¹ñ³Ù)
B47: Ü51 ¨ Ü52 ÝáñÙ³ïÇíÝ»ñ
B48: ²ñÅáõÛÃ | C48: Ü³Ëáñ¹ »ñÏáõ »é³ÙëÛ³ÏÝ»ñÇ ÙÇçÇÝ | D48: ºé³ÙëÛ³ÏÇ ÁÝÃ³óùáõÙ ÷³ëï³óÇ ïñ³Ù³¹ñí³Í ¨ Ü51, Ü52 ÝáñÙ³ïÇíÝ»ñÇÝ ãµ³í³ñ³ñáÕ í³ñÏ»ñ | E48: ö³ëï³óÇ ß»ÕáõÙ | F48: ÂáõÛÉ³ïñ»ÉÇ ß»ÕáõÙ
B49: ÐÐ ¹ñ³Ù | E49: =D49/C49 -> #DIV/0!
B50: ²ñï³ñÅáõÛÃ | E50: =D50/C50 -> #DIV/0!
D69: ì³ñÏ³ÛÇÝ Ï³½Ù³Ï»ñåáõÃÛ³Ý í³ñãáõÃÛ³Ý Ý³Ë³·³Ñ
D70: (·áñÍ³¹Çñ ïÝûñ»Ý)
B71: Î.î. | D71: ¶ÉË³íáñ Ñ³ßí³å³Ñ

Sheet Sheet2
B1: ÜáñÙ³ïÇíÝ»ñÇ Ñ³ßí³ñÏÇ Ù»ç ÁÝ¹·ñÏíáÕ ÙÇçÇÝ óáõó³ÝÇßÝ»ñÇ Ñ³ßí³ñÏÁ
B3: ²Ùë³ÃÇíÁ | C3: =IF(Sheet1!D11<>"",Sheet1!D11,"") -> 46054 | D3: Ã. -Çó ÙÇÝã¨ | E3: =IF(Sheet1!F11<>"",Sheet1!F11,"") -> 46081
A5: ÀÝ¹Ñ³Ýáõñ Ï³åÇï³ÉÇ ¨ Ýñ³ ï³ññ»ñÇ Ñ³ßí³ñÏÝ Áëï ûñ»ñÇ | K5: (Ñ³½. ¹ñ³Ù)
A6: ²Ùëí³ ûñ»ñÁ | B6: ÐÇÙÝ³Ï³Ý Ï³åÇï³É | C6: Èñ³óáõóÇã Ï³åÇï³É | D6: ÀÝ¹Ñ³Ýáõñ Ï³åÇï³É | E6: ÜáñÙ³ïÇí³ÛÇÝ Ï³åÇï³ÉÇ Ñ³ßí³ñÏÇ Ñ³Ù³ñ ³ÝÑñ³Å»ßï ÑÇÙÝ³Ï³Ý Ï³åÇï³ÉÇó å³Ï³ë»óíáÕ ·áõÙ³ñÝ»ñ | F6: ÜáñÙ³ïÇí³ÛÇÝ Éñ³óáõóÇã Ï³åÇï³ÉÇ Ñ³ßí³ñÏÇÝ Ù³ëÝ³ÏóáÕ ·áõÙ³ñÝ»ñ | H6: ÜáñÙ³ïÇíÝ»ñÇ Ñ³ßí³ñÏÇÝ Ù³ëÝ³ÏóáÕ
F7: ÀÝ¹·ñÏíáÕ ·áõÙ³ñÝ»ñ | G7: âÁÝ¹·ñÏíáÕ ·áõÙ³ñÝ»ñ | H7: ÐÇÙÝ³Ï³Ý Ï³åÇï³É (1-4) | I7: Èñ³óáõóÇã Ï³åÇï³É (2+5-6) | J7: Èñ³óáõóÇã Ï³åÇï³É (áã ³í»ÉÇ, ù³Ý ÑÇÙÝ³Ï³Ý Ï³åÇï³ÉÇ 50%) | K7: ÀÝ¹Ñ³Ýáõñ Ï³åÇï³É (7+9)
B8: 1 | C8: 2 | D8: 3 | E8: 4 | F8: 5 | G8: 6 | H8: 7 | I8: 8 | J8: 9 | K8: 10
A9: 1 | D9: =IF(TRIM(B9)<>"",SUM(B9:C9),"") | H9: =IF(TRIM(B9)<>"",B9-E9,"") | I9: =IF(TRIM(B9)<>"",C9+F9-G9,"") | J9: =IF(TRIM(I9)<>"",IF(H9<=0,IF(I9<=0,I9,0),IF(I9>H9/2,H9/2,I9))," ") | K9: =IF(TRIM(B9)<>"",SUM(H9,J9),"")
A10: 2 | D10: =IF(TRIM(B10)<>"",SUM(B10:C10),"") | H10: =IF(TRIM(B10)<>"",B10-E10,"") | I10: =IF(TRIM(B10)<>"",C10+F10-G10,"") | J10: =IF(TRIM(I10)<>"",IF(H10<=0,IF(I10<=0,I10,0),IF(I10>H10/2,H10/2,I10))," ") | K10: =IF(TRIM(B10)<>"",SUM(H10,J10),"")
A11: 3 | D11: =IF(TRIM(B11)<>"",SUM(B11:C11),"") | H11: =IF(TRIM(B11)<>"",B11-E11,"") | I11: =IF(TRIM(B11)<>"",C11+F11-G11,"") | J11: =IF(TRIM(I11)<>"",IF(H11<=0,IF(I11<=0,I11,0),IF(I11>H11/2,H11/2,I11))," ") | K11: =IF(TRIM(B11)<>"",SUM(H11,J11),"")
A12: 4 | D12: =IF(TRIM(B12)<>"",SUM(B12:C12),"") | H12: =IF(TRIM(B12)<>"",B12-E12,"") | I12: =IF(TRIM(B12)<>"",C12+F12-G12,"") | J12: =IF(TRIM(I12)<>"",IF(H12<=0,IF(I12<=0,I12,0),IF(I12>H12/2,H12/2,I12))," ") | K12: =IF(TRIM(B12)<>"",SUM(H12,J12),"")
A13: 5 | D13: =IF(TRIM(B13)<>"",SUM(B13:C13),"") | H13: =IF(TRIM(B13)<>"",B13-E13,"") | I13: =IF(TRIM(B13)<>"",C13+F13-G13,"") | J13: =IF(TRIM(I13)<>"",IF(H13<=0,IF(I13<=0,I13,0),IF(I13>H13/2,H13/2,I13))," ") | K13: =IF(TRIM(B13)<>"",SUM(H13,J13),"")
A14: 6 | D14: =IF(TRIM(B14)<>"",SUM(B14:C14),"") | H14: =IF(TRIM(B14)<>"",B14-E14,"") | I14: =IF(TRIM(B14)<>"",C14+F14-G14,"") | J14: =IF(TRIM(I14)<>"",IF(H14<=0,IF(I14<=0,I14,0),IF(I14>H14/2,H14/2,I14))," ") | K14: =IF(TRIM(B14)<>"",SUM(H14,J14),"")
A15: 7 | D15: =IF(TRIM(B15)<>"",SUM(B15:C15),"") | H15: =IF(TRIM(B15)<>"",B15-E15,"") | I15: =IF(TRIM(B15)<>"",C15+F15-G15,"") | J15: =IF(TRIM(I15)<>"",IF(H15<=0,IF(I15<=0,I15,0),IF(I15>H15/2,H15/2,I15))," ") | K15: =IF(TRIM(B15)<>"",SUM(H15,J15),"")
A16: 8 | D16: =IF(TRIM(B16)<>"",SUM(B16:C16),"") | H16: =IF(TRIM(B16)<>"",B16-E16,"") | I16: =IF(TRIM(B16)<>"",C16+F16-G16,"") | J16: =IF(TRIM(I16)<>"",IF(H16<=0,IF(I16<=0,I16,0),IF(I16>H16/2,H16/2,I16))," ") | K16: =IF(TRIM(B16)<>"",SUM(H16,J16),"")
A17: 9 | D17: =IF(TRIM(B17)<>"",SUM(B17:C17),"") | H17: =IF(TRIM(B17)<>"",B17-E17,"") | I17: =IF(TRIM(B17)<>"",C17+F17-G17,"") | J17: =IF(TRIM(I17)<>"",IF(H17<=0,IF(I17<=0,I17,0),IF(I17>H17/2,H17/2,I17))," ") | K17: =IF(TRIM(B17)<>"",SUM(H17,J17),"")
A18: 10 | D18: =IF(TRIM(B18)<>"",SUM(B18:C18),"") | H18: =IF(TRIM(B18)<>"",B18-E18,"") | I18: =IF(TRIM(B18)<>"",C18+F18-G18,"") | J18: =IF(TRIM(I18)<>"",IF(H18<=0,IF(I18<=0,I18,0),IF(I18>H18/2,H18/2,I18))," ") | K18: =IF(TRIM(B18)<>"",SUM(H18,J18),"")
A19: 11 | D19: =IF(TRIM(B19)<>"",SUM(B19:C19),"") | H19: =IF(TRIM(B19)<>"",B19-E19,"") | I19: =IF(TRIM(B19)<>"",C19+F19-G19,"") | J19: =IF(TRIM(I19)<>"",IF(H19<=0,IF(I19<=0,I19,0),IF(I19>H19/2,H19/2,I19))," ") | K19: =IF(TRIM(B19)<>"",SUM(H19,J19),"")
A20: 12 | D20: =IF(TRIM(B20)<>"",SUM(B20:C20),"") | H20: =IF(TRIM(B20)<>"",B20-E20,"") | I20: =IF(TRIM(B20)<>"",C20+F20-G20,"") | J20: =IF(TRIM(I20)<>"",IF(H20<=0,IF(I20<=0,I20,0),IF(I20>H20/2,H20/2,I20))," ") | K20: =IF(TRIM(B20)<>"",SUM(H20,J20),"")
... A39: 31 | D39: =IF(TRIM(B39)<>"",SUM(B39:C39),"") | H39: =IF(TRIM(B39)<>"",B39-E39,"") | I39: =IF(TRIM(B39)<>"",C39+F39-G39,"") | J39: =IF(TRIM(I39)<>"",IF(H39<=0,IF(I39<=0,I39,0),IF(I39>H39/2,H39/2,I39))," ") | K39: =IF(TRIM(B39)<>"",SUM(H39,J39),"")
A40: ØÇçÇÝ | B40: =SUM(B9:B39)/(Date2-Date1+1) -> 0 | C40: =SUM(C9:C39)/(Date2-Date1+1) -> 0 | D40: =SUM(D9:D39)/(Date2-Date1+1) -> 0 | E40: =SUM(E9:E39)/(Date2-Date1+1) -> 0 | F40: =SUM(F9:F39)/(Date2-Date1+1) -> 0 | G40: =SUM(G9:G39)/(Date2-Date1+1) -> 0 | H40: =SUM(H9:H39)/(Date2-Date1+1) -> 0 | I40: =SUM(I9:I39)/(Date2-Date1+1) -> 0 | ... K40: =SUM(K9:K39)/(Date2-Date1+1) -> 0

Sheet Sheet3
A1: ÜáñÙ³ïÇíÝ»ñÇ Ñ³ßí³ñÏÇ Ù»ç ÁÝ¹·ñÏíáÕ ÙÇçÇÝ óáõó³ÝÇßÝ»ñÇ Ñ³ßí³ñÏÁ
A2: (ß³ñáõÝ³ÏáõÃÛáõÝ)
A4: èÇëÏáí Ïßéí³Í ³ÏïÇíÝ»ñÇ Ñ³ßí³ñÏÝ Áëï ûñ»ñÇ
A5: Ð³ßí»Ïßé³ÛÇÝ Ñá¹í³ÍÝ»ñ Áëï éÇëÏ»ñÇ, ¹ñ³Ýó Ñ³Ù³å³ï³ëË³Ý ³ÏïÇíÝ»ñÇ ÑÝ³ñ³íáñ ÏáñáõëïÝ»ñÇ Ù³ëÑ³ÝáõÙÝ»ñ
A6: ²Ùëí³ ûñ»ñÁ | B6: èÇëÏÇ 0 % ÏßÇé | C6: ²ÏïÇíÇ ÑÝ³ñ³íáñ ÏáñáõëïÇ Ù³ëÑ³ÝáõÙ | D6: èÇëÏÇ 10 % ÏßÇé | E6: ²ÏïÇíÇ ÑÝ³ñ³íáñ ÏáñáõëïÇ Ù³ëÑ³ÝáõÙ | F6: èÇëÏÇ 20 % ÏßÇé | G6: ²ÏïÇíÇ ÑÝ³ñ³íáñ ÏáñáõëïÇ Ù³ëÑ³ÝáõÙ | H6: èÇëÏÇ 30 % ÏßÇé | I6: ²ÏïÇíÇ ÑÝ³ñ³íáñ ÏáñáõëïÇ Ù³ëÑ³ÝáõÙ | J6: èÇëÏÇ 50 % ÏßÇé | K6: ²ÏïÇíÇ ÑÝ³ñ³íáñ ÏáñáõëïÇ Ù³ëÑ³ÝáõÙ | L6: èÇëÏÇ 75 % ÏßÇé | M6: ²ÏïÇíÇ ÑÝ³ñ³íáñ ÏáñáõëïÇ Ù³ëÑ³ÝáõÙ | N6: èÇëÏÇ 85 % ÏßÇé | O6: ²ÏïÇíÇ ÑÝ³ñ³íáñ ÏáñáõëïÇ Ù³ëÑ³ÝáõÙ | P6: èÇëÏÇ 100 % ÏßÇé | Q6: ²ÏïÇíÇ ÑÝ³ñ³íáñ ÏáñáõëïÇ Ù³ëÑ³ÝáõÙ | R6: èÇëÏÇ 110 % ÏßÇé | S6: ²ÏïÇíÇ ÑÝ³ñ³íáñ ÏáñáõëïÇ Ù³ëÑ³ÝáõÙ | T6: èÇëÏÇ 125 % ÏßÇé | U6: ²ÏïÇíÇ ÑÝ³ñ³íáñ ÏáñáõëïÇ Ù³ëÑ³ÝáõÙ | V6: èÇëÏÇ 150 % ÏßÇé | W6: ²ÏïÇíÇ ÑÝ³ñ³íáñ ÏáñáõëïÇ Ù³ëÑ³ÝáõÙ | X6: èÇëÏÇ 225 % ÏßÇé | Y6: ²ÏïÇíÇ ÑÝ³ñ³íáñ ÏáñáõëïÇ Ù³ëÑ³ÝáõÙ | Z6: èÇëÏáí Ïßéí³Í ³ÏïÇíÝ»ñ [ (1-2)*0% + (3-4)*10%+(5-6)*20%+(7-8)*30%+(9-10)*50%+(11-12)*75%+(13-14)*85%+(15-16)*100%+(17-18)*110%+(19-20)*125%+(21-22)*150%+(23-24)*225%]
B7: 1 | C7: 2 | D7: 3 | E7: 4 | F7: 5 | G7: 6 | H7: 7 | I7: 8 | J7: 9 | K7: 10 | L7: 11 | M7: 12 | N7: 13 | O7: 14 | P7: 15 | Q7: 16 | R7: 17 | S7: 18 | T7: 19 | U7: 20 | V7: 21 | W7: 22 | X7: 23 | Y7: 24 | Z7: 25
A8: 1 | Z8: =(D8-E8)*0.1+(F8-G8)*0.2+(H8-I8)*0.3+(J8-K8)*0.5+(L8-M8)*0.75+(N8-O8)*0.85+(P8-Q8)+(R8-S8)*1.1+(T8-U8)*1.25+(V8-W8)*1.5+(X8-Y8)*2.25 -> 0
A9: 2 | Z9: =(D9-E9)*0.1+(F9-G9)*0.2+(H9-I9)*0.3+(J9-K9)*0.5+(L9-M9)*0.75+(N9-O9)*0.85+(P9-Q9)+(R9-S9)*1.1+(T9-U9)*1.25+(V9-W9)*1.5+(X9-Y9)*2.25 -> 0
A10: 3 | Z10: =(D10-E10)*0.1+(F10-G10)*0.2+(H10-I10)*0.3+(J10-K10)*0.5+(L10-M10)*0.75+(N10-O10)*0.85+(P10-Q10)+(R10-S10)*1.1+(T10-U10)*1.25+(V10-W10)*1.5+(X10-Y10)*2.25 -> 0
A11: 4 | Z11: =(D11-E11)*0.1+(F11-G11)*0.2+(H11-I11)*0.3+(J11-K11)*0.5+(L11-M11)*0.75+(N11-O11)*0.85+(P11-Q11)+(R11-S11)*1.1+(T11-U11)*1.25+(V11-W11)*1.5+(X11-Y11)*2.25 -> 0
A12: 5 | Z12: =(D12-E12)*0.1+(F12-G12)*0.2+(H12-I12)*0.3+(J12-K12)*0.5+(L12-M12)*0.75+(N12-O12)*0.85+(P12-Q12)+(R12-S12)*1.1+(T12-U12)*1.25+(V12-W12)*1.5+(X12-Y12)*2.25 -> 0
A13: 6 | Z13: =(D13-E13)*0.1+(F13-G13)*0.2+(H13-I13)*0.3+(J13-K13)*0.5+(L13-M13)*0.75+(N13-O13)*0.85+(P13-Q13)+(R13-S13)*1.1+(T13-U13)*1.25+(V13-W13)*1.5+(X13-Y13)*2.25 -> 0
A14: 7 | Z14: =(D14-E14)*0.1+(F14-G14)*0.2+(H14-I14)*0.3+(J14-K14)*0.5+(L14-M14)*0.75+(N14-O14)*0.85+(P14-Q14)+(R14-S14)*1.1+(T14-U14)*1.25+(V14-W14)*1.5+(X14-Y14)*2.25 -> 0
A15: 8 | Z15: =(D15-E15)*0.1+(F15-G15)*0.2+(H15-I15)*0.3+(J15-K15)*0.5+(L15-M15)*0.75+(N15-O15)*0.85+(P15-Q15)+(R15-S15)*1.1+(T15-U15)*1.25+(V15-W15)*1.5+(X15-Y15)*2.25 -> 0
A16: 9 | Z16: =(D16-E16)*0.1+(F16-G16)*0.2+(H16-I16)*0.3+(J16-K16)*0.5+(L16-M16)*0.75+(N16-O16)*0.85+(P16-Q16)+(R16-S16)*1.1+(T16-U16)*1.25+(V16-W16)*1.5+(X16-Y16)*2.25 -> 0
A17: 10 | Z17: =(D17-E17)*0.1+(F17-G17)*0.2+(H17-I17)*0.3+(J17-K17)*0.5+(L17-M17)*0.75+(N17-O17)*0.85+(P17-Q17)+(R17-S17)*1.1+(T17-U17)*1.25+(V17-W17)*1.5+(X17-Y17)*2.25 -> 0
A18: 11 | Z18: =(D18-E18)*0.1+(F18-G18)*0.2+(H18-I18)*0.3+(J18-K18)*0.5+(L18-M18)*0.75+(N18-O18)*0.85+(P18-Q18)+(R18-S18)*1.1+(T18-U18)*1.25+(V18-W18)*1.5+(X18-Y18)*2.25 -> 0
A19: 12 | Z19: =(D19-E19)*0.1+(F19-G19)*0.2+(H19-I19)*0.3+(J19-K19)*0.5+(L19-M19)*0.75+(N19-O19)*0.85+(P19-Q19)+(R19-S19)*1.1+(T19-U19)*1.25+(V19-W19)*1.5+(X19-Y19)*2.25 -> 0
... A38: 31 | Z38: =(D38-E38)*0.1+(F38-G38)*0.2+(H38-I38)*0.3+(J38-K38)*0.5+(L38-M38)*0.75+(N38-O38)*0.85+(P38-Q38)+(R38-S38)*1.1+(T38-U38)*1.25+(V38-W38)*1.5+(X38-Y38)*2.25 -> 0
A39: ØÇçÇÝ | B39: =IF(ISERROR(SUM(B8:B38)/(Date2-Date1+1)),0,(SUM(B8:B38)/(Date2-Date1+1))) -> 0 | C39: =IF(ISERROR(SUM(C8:C38)/(Date2-Date1+1)),0,(SUM(C8:C38)/(Date2-Date1+1))) -> 0 | D39: =IF(ISERROR(SUM(D8:D38)/(Date2-Date1+1)),0,(SUM(D8:D38)/(Date2-Date1+1))) -> 0 | E39: =IF(ISERROR(SUM(E8:E38)/(Date2-Date1+1)),0,(SUM(E8:E38)/(Date2-Date1+1))) -> 0 | F39: =IF(ISERROR(SUM(F8:F38)/(Date2-Date1+1)),0,(SUM(F8:F38)/(Date2-Date1+1))) -> 0 | G39: =IF(ISERROR(SUM(G8:G38)/(Date2-Date1+1)),0,(SUM(G8:G38)/(Date2-Date1+1))) -> 0 | H39: =IF(ISERROR(SUM(H8:H38)/(Date2-Date1+1)),0,(SUM(H8:H38)/(Date2-Date1+1))) -> 0 | I39: =IF(ISERROR(SUM(I8:I38)/(Date2-Date1+1)),0,(SUM(I8:I38)/(Date2-Date1+1))) -> 0 | ... Z39: =IF(ISERROR(SUM(Z8:Z38)/(Date2-Date1+1)),0,(SUM(Z8:Z38)/(Date2-Date1+1))) -> 0

Sheet Sheet4
A1: ÜáñÙ³ïÇíÝ»ñÇ Ñ³ßí³ñÏÇ Ù»ç ÁÝ¹·ñÏíáÕ ÙÇçÇÝ óáõó³ÝÇßÝ»ñÇ Ñ³ßí³ñÏÁ
A2: (ß³ñáõÝ³ÏáõÃÛáõÝ)
A4: èÇëÏáí Ïßéí³Í ³ÏïÇíÝ»ñÇ Ñ³ßí³ñÏÝ Áëï ûñ»ñÇ
A5: Ð»ïÑ³ßí»Ïßé³ÛÇÝ å³ÛÙ³Ý³Ï³Ý å³ñï³íáñáõÃÛáõÝÝ»ñ ¨ ³Ý³í³ñï Å³ÙÏ»ï³ÛÇÝ ·áñÍ³éÝáõÃÛáõÝÝ»ñ (Ñ»ïÑ³ßí»Ïßé³ÛÇÝ Ñá¹í³Í) Áëï éÇëÏÇ ÏßÇéÝ»ñÇ, ¹ñ³Ýó Ñ³Ù³å³ï³ëË³Ý å³ÑáõëïÝ»ñ
A6: ²Ùëí³ ûñ»ñÁ | B6: èÇëÏÇ 0% ÏßÇé | C6: ä³Ñáõëï | D6: èÇëÏÇ 10% ÏßÇé | E6: ä³Ñáõëï | F6: èÇëÏÇ 20% ÏßÇé | G6: ä³Ñáõëï | H6: èÇëÏÇ 30% ÏßÇé | I6: ä³Ñáõëï | J6: èÇëÏÇ 50% ÏßÇé | K6: ä³Ñáõëï | L6: èÇëÏÇ 75% ÏßÇé | M6: ä³Ñáõëï | N6: èÇëÏÇ 85% ÏßÇé | O6: ä³Ñáõëï | P6: èÇëÏÇ 100% ÏßÇé | Q6: ä³Ñáõëï | R6: èÇëÏÇ 110% ÏßÇé | S6: ä³Ñáõëï | T6: èÇëÏÇ 125% ÏßÇé | U6: ä³Ñáõëï | V6: èÇëÏÇ 150% ÏßÇé | W6: ä³Ñáõëï | X6: èÇëÏÇ 225% ÏßÇé | Y6: ä³Ñáõëï | Z6: èÇëÏáí Ïßéí³Í Ñ»ïÑ³ßí»Ïßé³ÛÇÝ Ñá¹í³ÍÝ»ñ[ (1-2)*0% + (3-4)*10%+(5-6)*20%+(7-8)*30%+(9-10)*50%+(11-12)*75%+(13-14)*85%+(15-16)*100%+(17-18)*110%+(19-20)*125%+(21-22)*150%+(23-24)*225%]
B7: 1 | C7: 2 | D7: 3 | E7: 4 | F7: 5 | G7: 6 | H7: 7 | I7: 8 | J7: 9 | K7: 10 | L7: 11 | M7: 12 | N7: 13 | O7: 14 | P7: 15 | Q7: 16 | R7: 17 | S7: 18 | T7: 19 | U7: 20 | V7: 21 | W7: 22 | X7: 23 | Y7: 24 | Z7: 25
A8: 1 | Z8: =(D8-E8)*0.1+(F8-G8)*0.2+(H8-I8)*0.3+(J8-K8)*0.5+(L8-M8)*0.75+(N8-O8)*0.85+(P8-Q8)+(R8-S8)*1.1+(T8-U8)*1.25+(V8-W8)*1.5+(X8-Y8)*2.25 -> 0
A9: 2 | Z9: =(D9-E9)*0.1+(F9-G9)*0.2+(H9-I9)*0.3+(J9-K9)*0.5+(L9-M9)*0.75+(N9-O9)*0.85+(P9-Q9)+(R9-S9)*1.1+(T9-U9)*1.25+(V9-W9)*1.5+(X9-Y9)*2.25 -> 0
A10: 3 | Z10: =(D10-E10)*0.1+(F10-G10)*0.2+(H10-I10)*0.3+(J10-K10)*0.5+(L10-M10)*0.75+(N10-O10)*0.85+(P10-Q10)+(R10-S10)*1.1+(T10-U10)*1.25+(V10-W10)*1.5+(X10-Y10)*2.25 -> 0
A11: 4 | Z11: =(D11-E11)*0.1+(F11-G11)*0.2+(H11-I11)*0.3+(J11-K11)*0.5+(L11-M11)*0.75+(N11-O11)*0.85+(P11-Q11)+(R11-S11)*1.1+(T11-U11)*1.25+(V11-W11)*1.5+(X11-Y11)*2.25 -> 0
A12: 5 | Z12: =(D12-E12)*0.1+(F12-G12)*0.2+(H12-I12)*0.3+(J12-K12)*0.5+(L12-M12)*0.75+(N12-O12)*0.85+(P12-Q12)+(R12-S12)*1.1+(T12-U12)*1.25+(V12-W12)*1.5+(X12-Y12)*2.25 -> 0
A13: 6 | Z13: =(D13-E13)*0.1+(F13-G13)*0.2+(H13-I13)*0.3+(J13-K13)*0.5+(L13-M13)*0.75+(N13-O13)*0.85+(P13-Q13)+(R13-S13)*1.1+(T13-U13)*1.25+(V13-W13)*1.5+(X13-Y13)*2.25 -> 0
A14: 7 | Z14: =(D14-E14)*0.1+(F14-G14)*0.2+(H14-I14)*0.3+(J14-K14)*0.5+(L14-M14)*0.75+(N14-O14)*0.85+(P14-Q14)+(R14-S14)*1.1+(T14-U14)*1.25+(V14-W14)*1.5+(X14-Y14)*2.25 -> 0
A15: 8 | Z15: =(D15-E15)*0.1+(F15-G15)*0.2+(H15-I15)*0.3+(J15-K15)*0.5+(L15-M15)*0.75+(N15-O15)*0.85+(P15-Q15)+(R15-S15)*1.1+(T15-U15)*1.25+(V15-W15)*1.5+(X15-Y15)*2.25 -> 0
A16: 9 | Z16: =(D16-E16)*0.1+(F16-G16)*0.2+(H16-I16)*0.3+(J16-K16)*0.5+(L16-M16)*0.75+(N16-O16)*0.85+(P16-Q16)+(R16-S16)*1.1+(T16-U16)*1.25+(V16-W16)*1.5+(X16-Y16)*2.25 -> 0
A17: 10 | Z17: =(D17-E17)*0.1+(F17-G17)*0.2+(H17-I17)*0.3+(J17-K17)*0.5+(L17-M17)*0.75+(N17-O17)*0.85+(P17-Q17)+(R17-S17)*1.1+(T17-U17)*1.25+(V17-W17)*1.5+(X17-Y17)*2.25 -> 0
A18: 11 | Z18: =(D18-E18)*0.1+(F18-G18)*0.2+(H18-I18)*0.3+(J18-K18)*0.5+(L18-M18)*0.75+(N18-O18)*0.85+(P18-Q18)+(R18-S18)*1.1+(T18-U18)*1.25+(V18-W18)*1.5+(X18-Y18)*2.25 -> 0
A19: 12 | Z19: =(D19-E19)*0.1+(F19-G19)*0.2+(H19-I19)*0.3+(J19-K19)*0.5+(L19-M19)*0.75+(N19-O19)*0.85+(P19-Q19)+(R19-S19)*1.1+(T19-U19)*1.25+(V19-W19)*1.5+(X19-Y19)*2.25 -> 0
... A38: 31 | Z38: =(D38-E38)*0.1+(F38-G38)*0.2+(H38-I38)*0.3+(J38-K38)*0.5+(L38-M38)*0.75+(N38-O38)*0.85+(P38-Q38)+(R38-S38)*1.1+(T38-U38)*1.25+(V38-W38)*1.5+(X38-Y38)*2.25 -> 0
A39: ØÇçÇÝ | B39: =IF(ISERROR(SUM(B8:B38)/(Date2-Date1+1)),0,(SUM(B8:B38)/(Date2-Date1+1))) -> 0 | C39: =IF(ISERROR(SUM(C8:C38)/(Date2-Date1+1)),0,(SUM(C8:C38)/(Date2-Date1+1))) -> 0 | D39: =IF(ISERROR(SUM(D8:D38)/(Date2-Date1+1)),0,(SUM(D8:D38)/(Date2-Date1+1))) -> 0 | E39: =IF(ISERROR(SUM(E8:E38)/(Date2-Date1+1)),0,(SUM(E8:E38)/(Date2-Date1+1))) -> 0 | F39: =IF(ISERROR(SUM(F8:F38)/(Date2-Date1+1)),0,(SUM(F8:F38)/(Date2-Date1+1))) -> 0 | G39: =IF(ISERROR(SUM(G8:G38)/(Date2-Date1+1)),0,(SUM(G8:G38)/(Date2-Date1+1))) -> 0 | H39: =IF(ISERROR(SUM(H8:H38)/(Date2-Date1+1)),0,(SUM(H8:H38)/(Date2-Date1+1))) -> 0 | I39: =IF(ISERROR(SUM(I8:I38)/(Date2-Date1+1)),0,(SUM(I8:I38)/(Date2-Date1+1))) -> 0 | ... Z39: =IF(ISERROR(SUM(Z8:Z38)/(Date2-Date1+1)),0,(SUM(Z8:Z38)/(Date2-Date1+1))) -> 0

Sheet Sheet5
A1: ÜáñÙ³ïÇíÝ»ñÇ Ñ³ßí³ñÏÇ Ù»ç ÁÝ¹·ñÏíáÕ ÙÇçÇÝ óáõó³ÝÇßÝ»ñÇ Ñ³ßí³ñÏÁ (ß³ñáõÝ³ÏáõÃÛáõÝ)
A4: ²ñï³ñÅáõÃ³ÛÇÝ éÇëÏÇ Ñ³ßí³ñÏ (êï³Ý¹³ñï Ù»Ãá¹³µ³ÝáõÃÛáõÝ)
A5: ²Ùëí³ ûñ»ñÁ | B5: ²ñï³ñÅáõÃ³ÛÇÝ »ñÏ³ñ ¹Çñù»ñÇ Ñ³Ýñ³·áõÙ³ñ | C5: ²ñï³ñÅáõÃ³ÛÇÝ Ï³ñ× ¹Çñù»ñÇ Ñ³Ýñ³·áõÙ³ñ (µ³ó³ñÓ³Ï Ù»ÍáõÃÛ³Ùµ) | D5: Â³ÝÏ³ñÅ»ù Ù»ï³ÕÝ»ñÇ µ³ÝÏ³ÛÇÝ ëï³Ý¹³ñï³óí³Í ÓáõÉ³ÏïáñÝ»ñÇ µ³ó ¹Çñù»ñÇ µ³ó³ñÓ³Ï Ù»ÍáõÃÛáõÝÝ»ñÇ Ñ³Ýñ³·áõÙ³ñ | E5: ²ñï³ñÅáõÃ³ÛÇÝ ³é³í»É³·áõÛÝ ¹ÇñùÁ | F5: ²ñï³ñÅáõÃ³ÛÇÝ éÇëÏ (4) * 12%
B7: 1 | C7: 2 | D7: 3 | E7: 4 | F7: 5
A8: 1 | E8: =MAX(B8,C8)+D8 -> 0 | F8: =E8*12% -> 0
A9: 2 | E9: =MAX(B9,C9)+D9 -> 0 | F9: =E9*12% -> 0
A10: 3 | E10: =MAX(B10,C10)+D10 -> 0 | F10: =E10*12% -> 0
A11: 4 | E11: =MAX(B11,C11)+D11 -> 0 | F11: =E11*12% -> 0
A12: 5 | E12: =MAX(B12,C12)+D12 -> 0 | F12: =E12*12% -> 0
A13: 6 | E13: =MAX(B13,C13)+D13 -> 0 | F13: =E13*12% -> 0
A14: 7 | E14: =MAX(B14,C14)+D14 -> 0 | F14: =E14*12% -> 0
A15: 8 | E15: =MAX(B15,C15)+D15 -> 0 | F15: =E15*12% -> 0
A16: 9 | E16: =MAX(B16,C16)+D16 -> 0 | F16: =E16*12% -> 0
A17: 10 | E17: =MAX(B17,C17)+D17 -> 0 | F17: =E17*12% -> 0
A18: 11 | E18: =MAX(B18,C18)+D18 -> 0 | F18: =E18*12% -> 0
A19: 12 | E19: =MAX(B19,C19)+D19 -> 0 | F19: =E19*12% -> 0
... A38: 31 | E38: =MAX(B38,C38)+D38 -> 0 | F38: =E38*12% -> 0
A39: ²é³í»É³·áõÛÝ | F39: =MAX(F8:F38) -> 0

Sheet Sheet6
A1: ÜáñÙ³ïÇíÝ»ñÇ Ñ³ßí³ñÏÇ Ù»ç ÁÝ¹·ñÏíáÕ ÙÇçÇÝ óáõó³ÝÇßÝ»ñÇ Ñ³ßí³ñÏÁ (ß³ñáõÝ³ÏáõÃÛáõÝ)
C3: ²ñï³ñÅáõÃ³ÛÇÝ éÇëÏÇ Ñ³ßí³ñÏ (ì³è Ù»Ãá¹³µ³ÝáõÃÛáõÝ)
A7: ²Ùëí³ ûñ»ñÁ | B7: úñ³Ï³Ý ì³è | C7: î³ëÝûñÛ³ ì³è | D7: ¶»ñ³½³ÝóáÕ ûñ»ñÇ ù³Ý³ÏÁ | E7: ¶ | F7: ²ñï³ñÅáõÃ³ÛÇÝ éÇëÏ
B9: 1 | C9: 2 | D9: 3 | E9: 4 | F9: 5
A10: 1 | C10: =SUMIF(A10:A40,DAY(Sheet1!F11),B10:B40)*SQRT(10) -> 0 | E10: =IF(D10<=4,3,IF(D10=5,3.4,IF(D10=6,3.5,IF(D10=7,3.65,IF(D10=8,3.75,IF(D10=9,3.85,IF(D10>=10,4,))))))) -> 3 | F10: =IF(B41="",0,3*(MAX(C10,E10*B41))) -> 0
A11: 2
A12: 3
A13: 4
A14: 5
A15: 6
A16: 7
A17: 8
A18: 9
A19: 10
A20: 11
A21: 12
A22: 13
... A39: 30
A40: 31 | F40: ¿ç 6
A41: ØÇçÇÝ | B41: =IF(ISERROR(AVERAGE(B10:B40)),"",(AVERAGE(B10:B40)))

Sheet Sheet7
A1: Ü51 ¨ Ü52 ÝáñÙ³ïÇíÝ»ñÇ Ñ³ßí³ñÏÇ Ù»ç ÁÝ¹·ñÏíáÕ óáõó³ÝÇßÝ»ñÇ í»ñ³µ»ñÛ³É
A4: Ð/Ñ | B4: Üáñ ïñ³Ù³¹ñíáÕ í³ñÏÇ ï»ë³Ï | C4: Üáñ ïñ³Ù³¹ñíáÕ í³ñÏÇ ³ñÅáõÛÃ | D4: ÜáñÙ³ïÇíÇ ï»ë³Ï | E4: ä³Ñ³ÝçÇ ¨ ·ñ³íÇ ³ñÅ»ùÇ Ñ³ñ³µ»ñ³Ïóáõ-ÃÛáõÝ | F4: Üáñ ïñ³Ù³¹ñíáÕ í³ñÏÇ Ù³Ûñ ·áõÙ³ñ | G4: ø³Ý³Ï
B5: 1 | C5: 2 | D5: 3 | E5: 4 | F5: 5 | G5: 6 | Q5: Loan_ref | R5: CurrCode_ref | S5: Norm_ref | T5: LTV_ref
A6: 1 | Q6: Ò»éùµ»ñÙ³Ý í³ñÏ | R6: AED | S6: Ü51 | T6: [0%-10%]
A7: 2 | Q7: Î³éáõóÙ³Ý/í»ñ³Ï³éáõóÙ³Ý í³ñÏ | R7: AFN | S7: Ü52 | T7: (10%-20%]
A8: 3 | Q8: ì»ñ³Ýáñá·Ù³Ý í³ñÏ | R8: ALL | T8: (20%-30%]
A9: 4 | Q9: ²Ýß³ñÅ ·áõÛùáí ³å³Ñáíí³Í ³ÛÉ í³ñÏ | R9: AMD | T9: (30%-40%]
A10: 5 | R10: ANG | T10: (40%-50%]
A11: 6 | R11: AOA | T11: (50%-60%]
A12: 7 | R12: ARS | T12: (60%-65%]
A13: 8 | R13: AUD | T13: (65%-70%]
A14: 9 | R14: AWG | T14: (70%-75%]
A15: 10 | R15: AZN | T15: (75%-80%]
A16: 11 | R16: BAM | T16: (80%-85%]
A17: 12 | R17: BBD | T17: (85%-90%]
A18: 13 | R18: BDT | T18: (90%-95%]
A19: 14 | R19: BGN | T19: (95%-100%]
A20: 15 | R20: BHD | T20: (100%-120%]
A21: 16 | R21: BIF | T21: (120%-150%]
A22: 17 | R22: BMD | T22: >150
A23: 18 | R23: BND
A24: 19 | R24: BOB
A25: 20 | R25: BOV
A26: 21 | R26: BRL
A27: 22 | R27: BSD
A28: 23 | R28: BTN
A29: 24 | R29: BWP
A30: 25 | R30: BYN
A31: 26 | R31: BZD
A32: 27 | R32: CAD
A33: 28 | R33: CDF
A34: 29 | R34: CHE
... A105: 100 | R105: MXN
R106: MXV
R107: MYR
R108: MZN
R109: NAD
R110: NGN
R111: NIO
R112: NOK
...
